Workbook

Sheet HUONG_DAN
B2: SOP Tracker · [BRAND]
B3: Đi kèm sổ tay: SOP-A Đơn chuẩn, SOP-B Hậu mãi, KPI & tracking.
B5: Cách dùng
B6: 1. Ô vàng | C6: Nhập tay. Chỉ nhập ngày khi đã có BẰNG CHỨNG (mã PO, ảnh QC, lượt quét thật, POD).
B7: 2. Ô xám | C7: Tự tính: trạng thái, chủ trì hiện tại, cờ SLA, lead time. Không gõ đè.
B8: 3. Màu tiêu đề | C8: Màu = vị trí nhập cột đó: xanh dương CX · xanh lá SRC · xanh ngọc LOG · nâu OPS · tím FIN · xám tự tính.
B9: 4. Họp 09:00 | C9: Mở DASHBOARD → biểu đồ 'Cờ SLA đang bật'. Lọc từng cột ⚑ ở DON/CASE, giao người xử lý ngay.
B10: 5. Thứ Sáu | C10: OPS chụp DASHBOARD vào báo cáo tuần. Đếm case theo nguyên nhân gốc, quyết định tắt SKU/NCC.
B11: 6. Dữ liệu | C11: KHÔNG ghi tên, email, SĐT, địa chỉ khách. Mã đơn là khóa nối. Thông tin khách chỉ nằm trong Shopify.
B12: 7. Phân quyền | C12: Khi có nhiều người: tách bản cho từng vị trí hoặc dùng bản xem lọc. Tab chi phí và NCC để file riêng.
B13: 8. Dòng DEMO | C13: Dòng có mã DEMO-… chỉ để xem cách hoạt động. Xóa trước khi dùng thật.
B15: Cờ SLA
B16: ⚑ Chưa đặt NCC >24h | C16: Đã thanh toán > 1 ngày mà chưa có ngày Đặt NCC → SRC
B17: ⚑ NCC quá hẹn >2d | C17: Quá ngày hẹn NCC gửi 2 ngày chưa có vận đơn → SRC nhắc; +5d báo OPS; +7d đổi NCC
B18: ⚑ Sắp vượt ETA | C18: Còn ≤ 14 ngày tới ETA max mà chưa xuất → CX báo khách trước ≥ 7 ngày (case C2)
B19: ⚑ Vượt ETA | C19: Quá ETA max chưa giao → CX chủ động đề nghị tín dụng 5% hoặc hủy hoàn 100%
B20: ⚑ >7d chưa cập nhật KH | C20: Lần liên hệ gần nhất > 7 ngày → CX gửi cập nhật tuần, ghi ngày vào cột 'Cập nhật KH gần nhất'
B21: ⚑ Case phản hồi >24h | C21: Chưa có người thật trả lời sau 24h → CX, lên đầu họp 09:00
B22: ⚑ Case mở >7 ngày | C22: Case chưa đóng sau 7 ngày → OPS gọi khách
B23: ⚑ Duyệt sai cấp | C23: Người duyệt thấp hơn mức cần (≤50 CX · 51–150 OPS · >150 / hoàn 100% CEO) → OPS rà

Sheet DASHBOARD
B2: Bảng điều khiển vận hành
B3: ="Cập nhật theo ngày: "&TEXT(TODAY(),"dd/mm/yyyy")&" · dữ liệu từ tab DON và CASE" -> Cập nhật theo ngày: 04/10/2026 · dữ liệu từ tab DON và CASE
B5: Đơn đang chạy | E5: Giao trong khung | H5: Đặt NCC ≤ 24h | K5: Cờ đỏ đơn đang mở | P5: Đơn theo trạng thái
B6: =COUNTA(DON!$A$3:$A$402)-COUNTIF(DON!$T$3:$T$402,"99*")-COUNTIF(DON!$T$3:$T$402,"95*") -> 10 | E6: =IFERROR(COUNTIF(DON!$AB$3:$AB$402,"Có")/(COUNTIF(DON!$AB$3:$AB$402,"Có")+COUNTIF(DON!$AB$3:$AB$402,"Không")),"–") -> 1 | H6: =IFERROR(COUNTIFS(DON!$AE$3:$AE$402,"<=1")/COUNT(DON!$AE$3:$AE$402),"–") -> 0.88888889 | K6: =COUNTIF(DON!$W$3:$AA$402,"⚑") -> 8 | P6: Nhóm | Q6: Số
P7: 10 Mới | Q7: =COUNTIF(DON!$T$3:$T$402,"10 Mới") -> 0
E8: Mục tiêu ≥ 90% | H8: Mục tiêu ≥ 95% | K8: Mục tiêu 0 | P8: 20 Đã xác nhận | Q8: =COUNTIF(DON!$T$3:$T$402,"20 Đã xác nhận") -> 2
P9: 30 Đã đặt NCC | Q9: =COUNTIF(DON!$T$3:$T$402,"30 Đã đặt NCC") -> 2
B10: Case / đơn | E10: Phản hồi đầu (giờ, trung vị) | H10: Chargeback / đơn | K10: Chi phí case ròng (A$) | P10: 40 NCC đã gửi | Q10: =COUNTIF(DON!$T$3:$T$402,"40 NCC đã gửi") -> 0
B11: =IFERROR(COUNTA(CASE!$A$3:$A$202)/COUNTA(DON!$A$3:$A$402),"–") -> 0.41666667 | E11: =IFERROR(MEDIAN(CASE!$T$3:$T$202),"–") -> 2 | H11: =IFERROR(COUNTIF(CASE!$C$3:$C$202,"C7*")/COUNTA(DON!$A$3:$A$402),"–") -> 0 | K11: =SUM(CASE!$S$3:$S$202) -> 714 | P11: 50 QC đạt | Q11: =COUNTIF(DON!$T$3:$T$402,"50 QC đạt") -> 1
P12: 60 Đã xuất | Q12: =COUNTIF(DON!$T$3:$T$402,"60 Đã xuất") -> 2
B13: Mục tiêu ≤ 3% | E13: Mục tiêu ≤ 4 | H13: Mục tiêu ≤ 0,5% | P13: 70 Thông quan | Q13: =COUNTIF(DON!$T$3:$T$402,"70 Thông quan") -> 1
P14: 80 Đang giao | Q14: =COUNTIF(DON!$T$3:$T$402,"80 Đang giao") -> 0
P15: 90 Đã giao | Q15: =COUNTIF(DON!$T$3:$T$402,"90 Đã giao") -> 2
P16: 95 Hủy/hoàn | Q16: =COUNTIF(DON!$T$3:$T$402,"95 Hủy/hoàn") -> 1
P17: 99 Đóng | Q17: =COUNTIF(DON!$T$3:$T$402,"99 Đóng") -> 1
P19: Lead time TB theo giai đoạn (ngày)
P20: Giai đoạn | Q20: Ngày TB
P21: S1–S2 TT→Đặt NCC | Q21: =IFERROR(AVERAGE(DON!$AE$3:$AE$402),0) -> 1.1111111
P22: S3 Đặt→NCC gửi | Q22: =IFERROR(AVERAGE(DON!$AF$3:$AF$402),0) -> 16.571429
P23: S4 Gửi→QC đạt | Q23: =IFERROR(AVERAGE(DON!$AG$3:$AG$402),0) -> 4
P24: S5 QC→Xuất | Q24: =IFERROR(AVERAGE(DON!$AH$3:$AH$402),0) -> 4.6666667
P25: S6–S7 Xuất→Giao | Q25: =IFERROR(AVERAGE(DON!$AI$3:$AI$402),0) -> 30
P27: Cờ SLA đang bật
P28: Nhóm | Q28: Số
P29: Chưa đặt NCC >24h | Q29: =COUNTIF(DON!$W$3:$W$402,"⚑") -> 1
P30: NCC quá hẹn >2d | Q30: =COUNTIF(DON!$X$3:$X$402,"⚑") -> 2
P31: Sắp vượt ETA | Q31: =COUNTIF(DON!$Y$3:$Y$402,"⚑") -> 0
P32: Vượt ETA | Q32: =COUNTIF(DON!$Z$3:$Z$402,"⚑") -> 0
P33: >7d chưa cập nhật KH | Q33: =COUNTIF(DON!$AA$3:$AA$402,"⚑") -> 5
P34: Case phản hồi >24h | Q34: =COUNTIF(CASE!$V$3:$V$202,"⚑") -> 1
P35: Case mở >7 ngày | Q35: =COUNTIF(CASE!$W$3:$W$202,"⚑") -> 1
P36: Case duyệt sai cấp | Q36: =COUNTIF(CASE!$X$3:$X$202,"⚑") -> 1
P38: Case theo loại
P39: Nhóm | Q39: Số
P40: C1 Hủy đơn | Q40: =COUNTIF(CASE!$C$3:$C$202,"C1 Hủy đơn") -> 1
P41: C2 Trễ hạn | Q41: =COUNTIF(CASE!$C$3:$C$202,"C2 Trễ hạn") -> 1
P42: C3 Hư hỏng | Q42: =COUNTIF(CASE!$C$3:$C$202,"C3 Hư hỏng") -> 1
P43: C4 Thiếu kiện/phụ kiện | Q43: =COUNTIF(CASE!$C$3:$C$202,"C4 Thiếu kiện/phụ kiện") -> 1
P44: C5 Sai hàng/khác mô tả | Q44: =COUNTIF(CASE!$C$3:$C$202,"C5 Sai hàng/khác mô tả") -> 0
P45: C6 Đổi ý | Q45: =COUNTIF(CASE!$C$3:$C$202,"C6 Đổi ý") -> 0
...

Sheet DON
A1: SOP-A · Theo dõi đơn — ô vàng: nhập ngày khi có BẰNG CHỨNG · cột xám: tự tính · màu tiêu đề = vị trí nhập
A2: Mã đơn | B2: Thị trường | C2: SKU | D2: Giá trị (A$) | E2: Ngày thanh toán | F2: ETA min | G2: ETA max (đã hứa) | H2: 20 Xác nhận | I2: 30 Đặt NCC | J2: Hẹn NCC gửi | K2: 40 NCC gửi | L2: 50 QC đạt | M2: 60 Xuất (quét thật) | N2: 70 Thông quan | O2: 80 Bàn giao giao cuối | P2: 90 Đã giao (POD) | Q2: 99 Đóng | R2: 95 Hủy/hoàn | S2: Cập nhật KH gần nhất | T2: Trạng thái | U2: Chủ trì hiện tại | V2: Ngày ở trạng thái | W2: ⚑ Chưa đặt NCC >24h | X2: ⚑ NCC quá hẹn >2d | Y2: ⚑ Sắp vượt ETA (≤14d) | Z2: ⚑ Vượt ETA | AA2: ⚑ >7d chưa cập nhật KH | AB2: Giao trong khung | AC2: Lead time tổng (ngày) | AD2: Số case | AE2: S1–S2 TT→Đặt NCC | AF2: S3 Đặt→NCC gửi | AG2: S4 Gửi→QC đạt | AH2: S5 QC→Xuất | AI2: S6–S7 Xuất→Giao
A3: DEMO-1001 | B3: AU | C3: TVC-OAK-180 | D3: 980 | E3: 46204 | F3: =IF($E3="","",$E3+7*IFERROR(VLOOKUP($B3,DS!$K$2:$M$4,2,FALSE()),12)) -> 46260 | G3: =IF($E3="","",$E3+7*IFERROR(VLOOKUP($B3,DS!$K$2:$M$4,3,FALSE()),12)) -> 46288 | H3: 46204 | I3: 46205 | J3: 46219 | K3: 46220 | L3: 46225 | M3: 46229 | N3: 46254 | O3: 46263 | P3: 46266 | Q3: 46280 | S3: 46259 | T3: =IF($A3="","",IF($R3<>"","95 Hủy/hoàn",IF($Q3<>"","99 Đóng",IF($P3<>"","90 Đã giao",IF($O3<>"","80 Đang giao",IF($N3<>"","70 Thông quan",IF($M3<>"","60 Đã xuất",IF($L3<>"","50 QC đạt",IF($K3<>"","40 NCC đã gửi",IF($I3<>"","30 Đã đặt NCC",IF($H3<>"","20 Đã xác nhận","10 Mới"))))))))))) -> 99 Đóng | U3: =IF($T3="","",IFERROR(VLOOKUP($T3,DS!$A$2:$B$12,2,FALSE()),"")) -> – | V3: =IF(OR($T3="",LEFT($T3,2)="99",LEFT($T3,2)="95"),"",TODAY()-MAX($E3,$H3:$P3)) | W3: =IF(AND($E3<>"",$I3="",$R3=""),IF(TODAY()-$E3>1,"⚑",""),"") | X3: =IF(AND($J3<>"",$K3="",$R3=""),IF(TODAY()-$J3>2,"⚑",""),"") | Y3: =IF(AND($G3<>"",$M3="",$R3=""),IF(AND($G3-TODAY()<=14,$G3>=TODAY()),"⚑",""),"") | Z3: =IF(AND($G3<>"",$P3="",$R3=""),IF(TODAY()>$G3,"⚑",""),"") | AA3: =IF(AND($E3<>"",$P3="",$R3=""),IF(TODAY()-MAX($E3,$H3,$M3,$S3)>7,"⚑",""),"") | AB3: =IF(OR($P3="",$G3=""),"",IF($P3<=$G3,"Có","Không")) -> Có | AC3: =IF(OR($P3="",$E3=""),"",$P3-$E3) -> 62 | AD3: =IF($A3="","",COUNTIF(CASE!$B$3:$B$202,$A3)) -> 1 | AE3: =IF(OR($I3="",$E3=""),"",$I3-$E3) -> 1 | AF3: =IF(OR($K3="",$I3=""),"",$K3-$I3) -> 15 | AG3: =IF(OR($L3="",$K3=""),"",$L3-$K3) -> 5 | AH3: =IF(OR($M3="",$L3=""),"",$M3-$L3) -> 4 | AI3: =IF(OR($P3="",$M3=""),"",$P3-$M3) -> 37
A4: DEMO-1002 | B4: AU | C4: CFT-WAL-120 | D4: 720 | E4: 46211 | F4: =IF($E4="","",$E4+7*IFERROR(VLOOKUP($B4,DS!$K$2:$M$4,2,FALSE()),12)) -> 46267 | G4: =IF($E4="","",$E4+7*IFERROR(VLOOKUP($B4,DS!$K$2:$M$4,3,FALSE()),12)) -> 46295 | H4: 46211 | I4: 46213 | J4: 46226 | K4: 46228 | L4: 46232 | M4: 46236 | N4: 46259 | O4: 46265 | P4: 46269 | S4: 46264 | T4: =IF($A4="","",IF($R4<>"","95 Hủy/hoàn",IF($Q4<>"","99 Đóng",IF($P4<>"","90 Đã giao",IF($O4<>"","80 Đang giao",IF($N4<>"","70 Thông quan",IF($M4<>"","60 Đã xuất",IF($L4<>"","50 QC đạt",IF($K4<>"","40 NCC đã gửi",IF($I4<>"","30 Đã đặt NCC",IF($H4<>"","20 Đã xác nhận","10 Mới"))))))))))) -> 90 Đã giao | U4: =IF($T4="","",IFERROR(VLOOKUP($T4,DS!$A$2:$B$12,2,FALSE()),"")) -> CX | V4: =IF(OR($T4="",LEFT($T4,2)="99",LEFT($T4,2)="95"),"",TODAY()-MAX($E4,$H4:$P4)) -> 30 | W4: =IF(AND($E4<>"",$I4="",$R4=""),IF(TODAY()-$E4>1,"⚑",""),"") | X4: =IF(AND($J4<>"",$K4="",$R4=""),IF(TODAY()-$J4>2,"⚑",""),"") | Y4: =IF(AND($G4<>"",$M4="",$R4=""),IF(AND($G4-TODAY()<=14,$G4>=TODAY()),"⚑",""),"") | Z4: =IF(AND($G4<>"",$P4="",$R4=""),IF(TODAY()>$G4,"⚑",""),"") | AA4: =IF(AND($E4<>"",$P4="",$R4=""),IF(TODAY()-MAX($E4,$H4,$M4,$S4)>7,"⚑",""),"") | AB4: =IF(OR($P4="",$G4=""),"",IF($P4<=$G4,"Có","Không")) -> Có | AC4: =IF(OR($P4="",$E4=""),"",$P4-$E4) -> 58 | AD4: =IF($A4="","",COUNTIF(CASE!$B$3:$B$202,$A4)) -> 1 | AE4: =IF(OR($I4="",$E4=""),"",$I4-$E4) -> 2 | AF4: =IF(OR($K4="",$I4=""),"",$K4-$I4) -> 15 | AG4: =IF(OR($L4="",$K4=""),"",$L4-$K4) -> 4 | AH4: =IF(OR($M4="",$L4=""),"",$M4-$L4) -> 4 | AI4: =IF(OR($P4="",$M4=""),"",$P4-$M4) -> 33
A5: DEMO-1003 | B5: SG | C5: SHO-WHT-100 | D5: 540 | E5: 46254 | F5: =IF($E5="","",$E5+7*IFERROR(VLOOKUP($B5,DS!$K$2:$M$4,2,FALSE()),12)) -> 46289 | G5: =IF($E5="","",$E5+7*IFERROR(VLOOKUP($B5,DS!$K$2:$M$4,3,FALSE()),12)) -> 46310 | H5: 46254 | I5: 46255 | J5: 46267 | K5: 46268 | L5: 46272 | M5: 46278 | N5: 46293 | O5: 46296 | P5: 46298 | S5: 46293 | T5: =IF($A5="","",IF($R5<>"","95 Hủy/hoàn",IF($Q5<>"","99 Đóng",IF($P5<>"","90 Đã giao",IF($O5<>"","80 Đang giao",IF($N5<>"","70 Thông quan",IF($M5<>"","60 Đã xuất",IF($L5<>"","50 QC đạt",IF($K5<>"","40 NCC đã gửi",IF($I5<>"","30 Đã đặt NCC",IF($H5<>"","20 Đã xác nhận","10 Mới"))))))))))) -> 90 Đã giao | U5: =IF($T5="","",IFERROR(VLOOKUP($T5,DS!$A$2:$B$12,2,FALSE()),"")) -> CX | V5: =IF(OR($T5="",LEFT($T5,2)="99",LEFT($T5,2)="95"),"",TODAY()-MAX($E5,$H5:$P5)) -> 1 | W5: =IF(AND($E5<>"",$I5="",$R5=""),IF(TODAY()-$E5>1,"⚑",""),"") | X5: =IF(AND($J5<>"",$K5="",$R5=""),IF(TODAY()-$J5>2,"⚑",""),"") | Y5: =IF(AND($G5<>"",$M5="",$R5=""),IF(AND($G5-TODAY()<=14,$G5>=TODAY()),"⚑",""),"") | Z5: =IF(AND($G5<>"",$P5="",$R5=""),IF(TODAY()>$G5,"⚑",""),"") | AA5: =IF(AND($E5<>"",$P5="",$R5=""),IF(TODAY()-MAX($E5,$H5,$M5,$S5)>7,"⚑",""),"") | AB5: =IF(OR($P5="",$G5=""),"",IF($P5<=$G5,"Có","Không")) -> Có | AC5: =IF(OR($P5="",$E5=""),"",$P5-$E5) -> 44 | AD5: =IF($A5="","",COUNTIF(CASE!$B$3:$B$202,$A5)) -> 1 | AE5: =IF(OR($I5="",$E5=""),"",$I5-$E5) -> 1 | AF5: =IF(OR($K5="",$I5=""),"",$K5-$I5) -> 13 | AG5: =IF(OR($L5="",$K5=""),"",$L5-$K5) -> 4 | AH5: =IF(OR($M5="",$L5=""),"",$M5-$L5) -> 6 | AI5: =IF(OR($P5="",$M5=""),"",$P5-$M5) -> 20
A6: DEMO-1004 | B6: AU | C6: BUF-BLK-160 | D6: 1250 | E6: 46229 | F6: =IF($E6="","",$E6+7*IFERROR(VLOOKUP($B6,DS!$K$2:$M$4,2,FALSE()),12)) -> 46285 | G6: =IF($E6="","",$E6+7*IFERROR(VLOOKUP($B6,DS!$K$2:$M$4,3,FALSE()),12)) -> 46313 | H6: 46229 | I6: 46230 | J6: 46244 | K6: 46249 | L6: 46253 | M6: 46258 | N6: 46287 | S6: 46287 | T6: =IF($A6="","",IF($R6<>"","95 Hủy/hoàn",IF($Q6<>"","99 Đóng",IF($P6<>"","90 Đã giao",IF($O6<>"","80 Đang giao",IF($N6<>"","70 Thông quan",IF($M6<>"","60 Đã xuất",IF($L6<>"","50 QC đạt",IF($K6<>"","40 NCC đã gửi",IF($I6<>"","30 Đã đặt NCC",IF($H6<>"","20 Đã xác nhận","10 Mới"))))))))))) -> 70 Thông quan | U6: =IF($T6="","",IFERROR(VLOOKUP($T6,DS!$A$2:$B$12,2,FALSE()),"")) -> LOG | V6: =IF(OR($T6="",LEFT($T6,2)="99",LEFT($T6,2)="95"),"",TODAY()-MAX($E6,$H6:$P6)) -> 12 | W6: =IF(AND($E6<>"",$I6="",$R6=""),IF(TODAY()-$E6>1,"⚑",""),"") | X6: =IF(AND($J6<>"",$K6="",$R6=""),IF(TODAY()-$J6>2,"⚑",""),"") | Y6: =IF(AND($G6<>"",$M6="",$R6=""),IF(AND($G6-TODAY()<=14,$G6>=TODAY()),"⚑",""),"") | Z6: =IF(AND($G6<>"",$P6="",$R6=""),IF(TODAY()>$G6,"⚑",""),"") | AA6: =IF(AND($E6<>"",$P6="",$R6=""),IF(TODAY()-MAX($E6,$H6,$M6,$S6)>7,"⚑",""),"") -> ⚑ | AB6: =IF(OR($P6="",$G6=""),"",IF($P6<=$G6,"Có","Không")) | AC6: =IF(OR($P6="",$E6=""),"",$P6-$E6) | AD6: =IF($A6="","",COUNTIF(CASE!$B$3:$B$202,$A6)) -> 0 | AE6: =IF(OR($I6="",$E6=""),"",$I6-$E6) -> 1 | AF6: =IF(OR($K6="",$I6=""),"",$K6-$I6) -> 19 | AG6: =IF(OR($L6="",$K6=""),"",$L6-$K6) -> 4 | AH6: =IF(OR($M6="",$L6=""),"",$M6-$L6) -> 5 | AI6: =IF(OR($P6="",$M6=""),"",$P6-$M6)
A7: DEMO-1005 | B7: AU | C7: BKS-OAK-080 | D7: 610 | E7: 46239 | F7: =IF($E7="","",$E7+7*IFERROR(VLOOKUP($B7,DS!$K$2:$M$4,2,FALSE()),12)) -> 46295 | G7: =IF($E7="","",$E7+7*IFERROR(VLOOKUP($B7,DS!$K$2:$M$4,3,FALSE()),12)) -> 46323 | H7: 46239 | I7: 46240 | J7: 46254 | K7: 46255 | L7: 46259 | M7: 46264 | S7: 46289 | T7: =IF($A7="","",IF($R7<>"","95 Hủy/hoàn",IF($Q7<>"","99 Đóng",IF($P7<>"","90 Đã giao",IF($O7<>"","80 Đang giao",IF($N7<>"","70 Thông quan",IF($M7<>"","60 Đã xuất",IF($L7<>"","50 QC đạt",IF($K7<>"","40 NCC đã gửi",IF($I7<>"","30 Đã đặt NCC",IF($H7<>"","20 Đã xác nhận","10 Mới"))))))))))) -> 60 Đã xuất | U7: =IF($T7="","",IFERROR(VLOOKUP($T7,DS!$A$2:$B$12,2,FALSE()),"")) -> LOG | V7: =IF(OR($T7="",LEFT($T7,2)="99",LEFT($T7,2)="95"),"",TODAY()-MAX($E7,$H7:$P7)) -> 35 | W7: =IF(AND($E7<>"",$I7="",$R7=""),IF(TODAY()-$E7>1,"⚑",""),"") | X7: =IF(AND($J7<>"",$K7="",$R7=""),IF(TODAY()-$J7>2,"⚑",""),"") | Y7: =IF(AND($G7<>"",$M7="",$R7=""),IF(AND($G7-TODAY()<=14,$G7>=TODAY()),"⚑",""),"") | Z7: =IF(AND($G7<>"",$P7="",$R7=""),IF(TODAY()>$G7,"⚑",""),"") | AA7: =IF(AND($E7<>"",$P7="",$R7=""),IF(TODAY()-MAX($E7,$H7,$M7,$S7)>7,"⚑",""),"") -> ⚑ | AB7: =IF(OR($P7="",$G7=""),"",IF($P7<=$G7,"Có","Không")) | AC7: =IF(OR($P7="",$E7=""),"",$P7-$E7) | AD7: =IF($A7="","",COUNTIF(CASE!$B$3:$B$202,$A7)) -> 0 | AE7: =IF(OR($I7="",$E7=""),"",$I7-$E7) -> 1 | AF7: =IF(OR($K7="",$I7=""),"",$K7-$I7) -> 15 | AG7: =IF(OR($L7="",$K7=""),"",$L7-$K7) -> 4 | AH7: =IF(OR($M7="",$L7=""),"",$M7-$L7) -> 5 | AI7: =IF(OR($P7="",$M7=""),"",$P7-$M7)
A8: DEMO-1006 | B8: AU | C8: DTB-WAL-180 | D8: 1490 | E8: 46259 | F8: =IF($E8="","",$E8+7*IFERROR(VLOOKUP($B8,DS!$K$2:$M$4,2,FALSE()),12)) -> 46315 | G8: =IF($E8="","",$E8+7*IFERROR(VLOOKUP($B8,DS!$K$2:$M$4,3,FALSE()),12)) -> 46343 | H8: 46259 | I8: 46260 | J8: 46275 | K8: 46284 | L8: 46287 | S8: 46290 | T8: =IF($A8="","",IF($R8<>"","95 Hủy/hoàn",IF($Q8<>"","99 Đóng",IF($P8<>"","90 Đã giao",IF($O8<>"","80 Đang giao",IF($N8<>"","70 Thông quan",IF($M8<>"","60 Đã xuất",IF($L8<>"","50 QC đạt",IF($K8<>"","40 NCC đã gửi",IF($I8<>"","30 Đã đặt NCC",IF($H8<>"","20 Đã xác nhận","10 Mới"))))))))))) -> 50 QC đạt | U8: =IF($T8="","",IFERROR(VLOOKUP($T8,DS!$A$2:$B$12,2,FALSE()),"")) -> LOG | V8: =IF(OR($T8="",LEFT($T8,2)="99",LEFT($T8,2)="95"),"",TODAY()-MAX($E8,$H8:$P8)) -> 12 | W8: =IF(AND($E8<>"",$I8="",$R8=""),IF(TODAY()-$E8>1,"⚑",""),"") | X8: =IF(AND($J8<>"",$K8="",$R8=""),IF(TODAY()-$J8>2,"⚑",""),"") | Y8: =IF(AND($G8<>"",$M8="",$R8=""),IF(AND($G8-TODAY()<=14,$G8>=TODAY()),"⚑",""),"") | Z8: =IF(AND($G8<>"",$P8="",$R8=""),IF(TODAY()>$G8,"⚑",""),"") | AA8: =IF(AND($E8<>"",$P8="",$R8=""),IF(TODAY()-MAX($E8,$H8,$M8,$S8)>7,"⚑",""),"") -> ⚑ | AB8: =IF(OR($P8="",$G8=""),"",IF($P8<=$G8,"Có","Không")) | AC8: =IF(OR($P8="",$E8=""),"",$P8-$E8) | AD8: =IF($A8="","",COUNTIF(CASE!$B$3:$B$202,$A8)) -> 0 | AE8: =IF(OR($I8="",$E8=""),"",$I8-$E8) -> 1 | AF8: =IF(OR($K8="",$I8=""),"",$K8-$I8) -> 24 | AG8: =IF(OR($L8="",$K8=""),"",$L8-$K8) -> 3 | AH8: =IF(OR($M8="",$L8=""),"",$M8-$L8) | AI8: =IF(OR($P8="",$M8=""),"",$P8-$M8)
A9: DEMO-1007 | B9: SG | C9: TVC-WHT-160 | D9: 830 | E9: 46279 | F9: =IF($E9="","",$E9+7*IFERROR(VLOOKUP($B9,DS!$K$2:$M$4,2,FALSE()),12)) -> 46314 | G9: =IF($E9="","",$E9+7*IFERROR(VLOOKUP($B9,DS!$K$2:$M$4,3,FALSE()),12)) -> 46335 | H9: 46279 | I9: 46280 | J9: 46293 | S9: 46293 | T9: =IF($A9="","",IF($R9<>"","95 Hủy/hoàn",IF($Q9<>"","99 Đóng",IF($P9<>"","90 Đã giao",IF($O9<>"","80 Đang giao",IF($N9<>"","70 Thông quan",IF($M9<>"","60 Đã xuất",IF($L9<>"","50 QC đạt",IF($K9<>"","40 NCC đã gửi",IF($I9<>"","30 Đã đặt NCC",IF($H9<>"","20 Đã xác nhận","10 Mới"))))))))))) -> 30 Đã đặt NCC | U9: =IF($T9="","",IFERROR(VLOOKUP($T9,DS!$A$2:$B$12,2,FALSE()),"")) -> SRC | V9: =IF(OR($T9="",LEFT($T9,2)="99",LEFT($T9,2)="95"),"",TODAY()-MAX($E9,$H9:$P9)) -> 6 | W9: =IF(AND($E9<>"",$I9="",$R9=""),IF(TODAY()-$E9>1,"⚑",""),"") | X9: =IF(AND($J9<>"",$K9="",$R9=""),IF(TODAY()-$J9>2,"⚑",""),"") -> ⚑ | Y9: =IF(AND($G9<>"",$M9="",$R9=""),IF(AND($G9-TODAY()<=14,$G9>=TODAY()),"⚑",""),"") | Z9: =IF(AND($G9<>"",$P9="",$R9=""),IF(TODAY()>$G9,"⚑",""),"") | AA9: =IF(AND($E9<>"",$P9="",$R9=""),IF(TODAY()-MAX($E9,$H9,$M9,$S9)>7,"⚑",""),"") | AB9: =IF(OR($P9="",$G9=""),"",IF($P9<=$G9,"Có","Không")) | AC9: =IF(OR($P9="",$E9=""),"",$P9-$E9) | AD9: =IF($A9="","",COUNTIF(CASE!$B$3:$B$202,$A9)) -> 0 | AE9: =IF(OR($I9="",$E9=""),"",$I9-$E9) -> 1 | AF9: =IF(OR($K9="",$I9=""),"",$K9-$I9) | AG9: =IF(OR($L9="",$K9=""),"",$L9-$K9) | AH9: =IF(OR($M9="",$L9=""),"",$M9-$L9) | AI9: =IF(OR($P9="",$M9=""),"",$P9-$M9)
A10: DEMO-1008 | B10: AU | C10: CFT-OAK-100 | D10: 690 | E10: 46287 | F10: =IF($E10="","",$E10+7*IFERROR(VLOOKUP($B10,DS!$K$2:$M$4,2,FALSE()),12)) -> 46343 | G10: =IF($E10="","",$E10+7*IFERROR(VLOOKUP($B10,DS!$K$2:$M$4,3,FALSE()),12)) -> 46371 | H10: 46287 | I10: 46288 | J10: 46296 | S10: 46287 | T10: =IF($A10="","",IF($R10<>"","95 Hủy/hoàn",IF($Q10<>"","99 Đóng",IF($P10<>"","90 Đã giao",IF($O10<>"","80 Đang giao",IF($N10<>"","70 Thông quan",IF($M10<>"","60 Đã xuất",IF($L10<>"","50 QC đạt",IF($K10<>"","40 NCC đã gửi",IF($I10<>"","30 Đã đặt NCC",IF($H10<>"","20 Đã xác nhận","10 Mới"))))))))))) -> 30 Đã đặt NCC | U10: =IF($T10="","",IFERROR(VLOOKUP($T10,DS!$A$2:$B$12,2,FALSE()),"")) -> SRC | V10: =IF(OR($T10="",LEFT($T10,2)="99",LEFT($T10,2)="95"),"",TODAY()-MAX($E10,$H10:$P10)) -> 3 | W10: =IF(AND($E10<>"",$I10="",$R10=""),IF(TODAY()-$E10>1,"⚑",""),"") | X10: =IF(AND($J10<>"",$K10="",$R10=""),IF(TODAY()-$J10>2,"⚑",""),"") -> ⚑ | Y10: =IF(AND($G10<>"",$M10="",$R10=""),IF(AND($G10-TODAY()<=14,$G10>=TODAY()),"⚑",""),"") | Z10: =IF(AND($G10<>"",$P10="",$R10=""),IF(TODAY()>$G10,"⚑",""),"") | AA10: =IF(AND($E10<>"",$P10="",$R10=""),IF(TODAY()-MAX($E10,$H10,$M10,$S10)>7,"⚑",""),"") -> ⚑ | AB10: =IF(OR($P10="",$G10=""),"",IF($P10<=$G10,"Có","Không")) | AC10: =IF(OR($P10="",$E10=""),"",$P10-$E10) | AD10: =IF($A10="","",COUNTIF(CASE!$B$3:$B$202,$A10)) -> 0 | AE10: =IF(OR($I10="",$E10=""),"",$I10-$E10) -> 1 | AF10: =IF(OR($K10="",$I10=""),"",$K10-$I10) | AG10: =IF(OR($L10="",$K10=""),"",$L10-$K10) | AH10: =IF(OR($M10="",$L10=""),"",$M10-$L10) | AI10: =IF(OR($P10="",$M10=""),"",$P10-$M10)
A11: DEMO-1009 | B11: AU | C11: SHO-GRY-120 | D11: 560 | E11: 46296 | F11: =IF($E11="","",$E11+7*IFERROR(VLOOKUP($B11,DS!$K$2:$M$4,2,FALSE()),12)) -> 46352 | G11: =IF($E11="","",$E11+7*IFERROR(VLOOKUP($B11,DS!$K$2:$M$4,3,FALSE()),12)) -> 46380 | H11: 46296 | S11: 46296 | T11: =IF($A11="","",IF($R11<>"","95 Hủy/hoàn",IF($Q11<>"","99 Đóng",IF($P11<>"","90 Đã giao",IF($O11<>"","80 Đang giao",IF($N11<>"","70 Thông quan",IF($M11<>"","60 Đã xuất",IF($L11<>"","50 QC đạt",IF($K11<>"","40 NCC đã gửi",IF($I11<>"","30 Đã đặt NCC",IF($H11<>"","20 Đã xác nhận","10 Mới"))))))))))) -> 20 Đã xác nhận | U11: =IF($T11="","",IFERROR(VLOOKUP($T11,DS!$A$2:$B$12,2,FALSE()),"")) -> SRC | V11: =IF(OR($T11="",LEFT($T11,2)="99",LEFT($T11,2)="95"),"",TODAY()-MAX($E11,$H11:$P11)) -> 3 | W11: =IF(AND($E11<>"",$I11="",$R11=""),IF(TODAY()-$E11>1,"⚑",""),"") -> ⚑ | X11: =IF(AND($J11<>"",$K11="",$R11=""),IF(TODAY()-$J11>2,"⚑",""),"") | Y11: =IF(AND($G11<>"",$M11="",$R11=""),IF(AND($G11-TODAY()<=14,$G11>=TODAY()),"⚑",""),"") | Z11: =IF(AND($G11<>"",$P11="",$R11=""),IF(TODAY()>$G11,"⚑",""),"") | AA11: =IF(AND($E11<>"",$P11="",$R11=""),IF(TODAY()-MAX($E11,$H11,$M11,$S11)>7,"⚑",""),"") | AB11: =IF(OR($P11="",$G11=""),"",IF($P11<=$G11,"Có","Không")) | AC11: =IF(OR($P11="",$E11=""),"",$P11-$E11) | AD11: =IF($A11="","",COUNTIF(CASE!$B$3:$B$202,$A11)) -> 0 | AE11: =IF(OR($I11="",$E11=""),"",$I11-$E11) | AF11: =IF(OR($K11="",$I11=""),"",$K11-$I11) | AG11: =IF(OR($L11="",$K11=""),"",$L11-$K11) | AH11: =IF(OR($M11="",$L11=""),"",$M11-$L11) | AI11: =IF(OR($P11="",$M11=""),"",$P11-$M11)
A12: DEMO-1010 | B12: AU | C12: BUF-OAK-140 | D12: 1100 | E12: 46298 | F12: =IF($E12="","",$E12+7*IFERROR(VLOOKUP($B12,DS!$K$2:$M$4,2,FALSE()),12)) -> 46354 | G12: =IF($E12="","",$E12+7*IFERROR(VLOOKUP($B12,DS!$K$2:$M$4,3,FALSE()),12)) -> 46382 | H12: 46298 | S12: 46298 | T12: =IF($A12="","",IF($R12<>"","95 Hủy/hoàn",IF($Q12<>"","99 Đóng",IF($P12<>"","90 Đã giao",IF($O12<>"","80 Đang giao",IF($N12<>"","70 Thông quan",IF($M12<>"","60 Đã xuất",IF($L12<>"","50 QC đạt",IF($K12<>"","40 NCC đã gửi",IF($I12<>"","30 Đã đặt NCC",IF($H12<>"","20 Đã xác nhận","10 Mới"))))))))))) -> 20 Đã xác nhận | U12: =IF($T12="","",IFERROR(VLOOKUP($T12,DS!$A$2:$B$12,2,FALSE()),"")) -> SRC | V12: =IF(OR($T12="",LEFT($T12,2)="99",LEFT($T12,2)="95"),"",TODAY()-MAX($E12,$H12:$P12)) -> 1 | W12: =IF(AND($E12<>"",$I12="",$R12=""),IF(TODAY()-$E12>1,"⚑",""),"") | X12: =IF(AND($J12<>"",$K12="",$R12=""),IF(TODAY()-$J12>2,"⚑",""),"") | Y12: =IF(AND($G12<>"",$M12="",$R12=""),IF(AND($G12-TODAY()<=14,$G12>=TODAY()),"⚑",""),"") | Z12: =IF(AND($G12<>"",$P12="",$R12=""),IF(TODAY()>$G12,"⚑",""),"") | AA12: =IF(AND($E12<>"",$P12="",$R12=""),IF(TODAY()-MAX($E12,$H12,$M12,$S12)>7,"⚑",""),"") | AB12: =IF(OR($P12="",$G12=""),"",IF($P12<=$G12,"Có","Không")) | AC12: =IF(OR($P12="",$E12=""),"",$P12-$E12) | AD12: =IF($A12="","",COUNTIF(CASE!$B$3:$B$202,$A12)) -> 0 | AE12: =IF(OR($I12="",$E12=""),"",$I12-$E12) | AF12: =IF(OR($K12="",$I12=""),"",$K12-$I12) | AG12: =IF(OR($L12="",$K12=""),"",$L12-$K12) | AH12: =IF(OR($M12="",$L12=""),"",$M12-$L12) | AI12: =IF(OR($P12="",$M12=""),"",$P12-$M12)
A13: DEMO-1011 | B13: AU | C13: DTB-OAK-160 | D13: 1320 | E13: 46219 | F13: =IF($E13="","",$E13+7*IFERROR(VLOOKUP($B13,DS!$K$2:$M$4,2,FALSE()),12)) -> 46275 | G13: =IF($E13="","",$E13+7*IFERROR(VLOOKUP($B13,DS!$K$2:$M$4,3,FALSE()),12)) -> 46303 | H13: 46219 | I13: 46220 | J13: 46234 | K13: 46235 | L13: 46239 | M13: 46243 | S13: 46291 | T13: =IF($A13="","",IF($R13<>"","95 Hủy/hoàn",IF($Q13<>"","99 Đóng",IF($P13<>"","90 Đã giao",IF($O13<>"","80 Đang giao",IF($N13<>"","70 Thông quan",IF($M13<>"","60 Đã xuất",IF($L13<>"","50 QC đạt",IF($K13<>"","40 NCC đã gửi",IF($I13<>"","30 Đã đặt NCC",IF($H13<>"","20 Đã xác nhận","10 Mới"))))))))))) -> 60 Đã xuất | U13: =IF($T13="","",IFERROR(VLOOKUP($T13,DS!$A$2:$B$12,2,FALSE()),"")) -> LOG | V13: =IF(OR($T13="",LEFT($T13,2)="99",LEFT($T13,2)="95"),"",TODAY()-MAX($E13,$H13:$P13)) -> 56 | W13: =IF(AND($E13<>"",$I13="",$R13=""),IF(TODAY()-$E13>1,"⚑",""),"") | X13: =IF(AND($J13<>"",$K13="",$R13=""),IF(TODAY()-$J13>2,"⚑",""),"") | Y13: =IF(AND($G13<>"",$M13="",$R13=""),IF(AND($G13-TODAY()<=14,$G13>=TODAY()),"⚑",""),"") | Z13: =IF(AND($G13<>"",$P13="",$R13=""),IF(TODAY()>$G13,"⚑",""),"") | AA13: =IF(AND($E13<>"",$P13="",$R13=""),IF(TODAY()-MAX($E13,$H13,$M13,$S13)>7,"⚑",""),"") -> ⚑ | AB13: =IF(OR($P13="",$G13=""),"",IF($P13<=$G13,"Có","Không")) | AC13: =IF(OR($P13="",$E13=""),"",$P13-$E13) | AD13: =IF($A13="","",COUNTIF(CASE!$B$3:$B$202,$A13)) -> 1 | AE13: =IF(OR($I13="",$E13=""),"",$I13-$E13) -> 1 | AF13: =IF(OR($K13="",$I13=""),"",$K13-$I13) -> 15 | AG13: =IF(OR($L13="",$K13=""),"",$L13-$K13) -> 4 | AH13: =IF(OR($M13="",$L13=""),"",$M13-$L13) -> 4 | AI13: =IF(OR($P13="",$M13=""),"",$P13-$M13)
A14: DEMO-1012 | B14: AU | C14: BKS-BLK-100 | D14: 650 | E14: 46269 | F14: =IF($E14="","",$E14+7*IFERROR(VLOOKUP($B14,DS!$K$2:$M$4,2,FALSE()),12)) -> 46325 | G14: =IF($E14="","",$E14+7*IFERROR(VLOOKUP($B14,DS!$K$2:$M$4,3,FALSE()),12)) -> 46353 | H14: 46269 | R14: 46270 | S14: 46270 | T14: =IF($A14="","",IF($R14<>"","95 Hủy/hoàn",IF($Q14<>"","99 Đóng",IF($P14<>"","90 Đã giao",IF($O14<>"","80 Đang giao",IF($N14<>"","70 Thông quan",IF($M14<>"","60 Đã xuất",IF($L14<>"","50 QC đạt",IF($K14<>"","40 NCC đã gửi",IF($I14<>"","30 Đã đặt NCC",IF($H14<>"","20 Đã xác nhận","10 Mới"))))))))))) -> 95 Hủy/hoàn | U14: =IF($T14="","",IFERROR(VLOOKUP($T14,DS!$A$2:$B$12,2,FALSE()),"")) -> – | V14: =IF(OR($T14="",LEFT($T14,2)="99",LEFT($T14,2)="95"),"",TODAY()-MAX($E14,$H14:$P14)) | W14: =IF(AND($E14<>"",$I14="",$R14=""),IF(TODAY()-$E14>1,"⚑",""),"") | X14: =IF(AND($J14<>"",$K14="",$R14=""),IF(TODAY()-$J14>2,"⚑",""),"") | Y14: =IF(AND($G14<>"",$M14="",$R14=""),IF(AND($G14-TODAY()<=14,$G14>=TODAY()),"⚑",""),"") | Z14: =IF(AND($G14<>"",$P14="",$R14=""),IF(TODAY()>$G14,"⚑",""),"") | AA14: =IF(AND($E14<>"",$P14="",$R14=""),IF(TODAY()-MAX($E14,$H14,$M14,$S14)>7,"⚑",""),"") | AB14: =IF(OR($P14="",$G14=""),"",IF($P14<=$G14,"Có","Không")) | AC14: =IF(OR($P14="",$E14=""),"",$P14-$E14) | AD14: =IF($A14="","",COUNTIF(CASE!$B$3:$B$202,$A14)) -> 1 | AE14: =IF(OR($I14="",$E14=""),"",$I14-$E14) | AF14: =IF(OR($K14="",$I14=""),"",$K14-$I14) | AG14: =IF(OR($L14="",$K14=""),"",$L14-$K14) | AH14: =IF(OR($M14="",$L14=""),"",$M14-$L14) | AI14: =IF(OR($P14="",$M14=""),"",$P14-$M14)
F15: =IF($E15="","",$E15+7*IFERROR(VLOOKUP($B15,DS!$K$2:$M$4,2,FALSE()),12)) | G15: =IF($E15="","",$E15+7*IFERROR(VLOOKUP($B15,DS!$K$2:$M$4,3,FALSE()),12)) | T15: =IF($A15="","",IF($R15<>"","95 Hủy/hoàn",IF($Q15<>"","99 Đóng",IF($P15<>"","90 Đã giao",IF($O15<>"","80 Đang giao",IF($N15<>"","70 Thông quan",IF($M15<>"","60 Đã xuất",IF($L15<>"","50 QC đạt",IF($K15<>"","40 NCC đã gửi",IF($I15<>"","30 Đã đặt NCC",IF($H15<>"","20 Đã xác nhận","10 Mới"))))))))))) | U15: =IF($T15="","",IFERROR(VLOOKUP($T15,DS!$A$2:$B$12,2,FALSE()),"")) | V15: =IF(OR($T15="",LEFT($T15,2)="99",LEFT($T15,2)="95"),"",TODAY()-MAX($E15,$H15:$P15)) | W15: =IF(AND($E15<>"",$I15="",$R15=""),IF(TODAY()-$E15>1,"⚑",""),"") | X15: =IF(AND($J15<>"",$K15="",$R15=""),IF(TODAY()-$J15>2,"⚑",""),"") | Y15: =IF(AND($G15<>"",$M15="",$R15=""),IF(AND($G15-TODAY()<=14,$G15>=TODAY()),"⚑",""),"") | Z15: =IF(AND($G15<>"",$P15="",$R15=""),IF(TODAY()>$G15,"⚑",""),"") | AA15: =IF(AND($E15<>"",$P15="",$R15=""),IF(TODAY()-MAX($E15,$H15,$M15,$S15)>7,"⚑",""),"") | AB15: =IF(OR($P15="",$G15=""),"",IF($P15<=$G15,"Có","Không")) | AC15: =IF(OR($P15="",$E15=""),"",$P15-$E15) | AD15: =IF($A15="","",COUNTIF(CASE!$B$3:$B$202,$A15)) | AE15: =IF(OR($I15="",$E15=""),"",$I15-$E15) | AF15: =IF(OR($K15="",$I15=""),"",$K15-$I15) | AG15: =IF(OR($L15="",$K15=""),"",$L15-$K15) | AH15: =IF(OR($M15="",$L15=""),"",$M15-$L15) | AI15: =IF(OR($P15="",$M15=""),"",$P15-$M15)
F16: =IF($E16="","",$E16+7*IFERROR(VLOOKUP($B16,DS!$K$2:$M$4,2,FALSE()),12)) | G16: =IF($E16="","",$E16+7*IFERROR(VLOOKUP($B16,DS!$K$2:$M$4,3,FALSE()),12)) | T16: =IF($A16="","",IF($R16<>"","95 Hủy/hoàn",IF($Q16<>"","99 Đóng",IF($P16<>"","90 Đã giao",IF($O16<>"","80 Đang giao",IF($N16<>"","70 Thông quan",IF($M16<>"","60 Đã xuất",IF($L16<>"","50 QC đạt",IF($K16<>"","40 NCC đã gửi",IF($I16<>"","30 Đã đặt NCC",IF($H16<>"","20 Đã xác nhận","10 Mới"))))))))))) | U16: =IF($T16="","",IFERROR(VLOOKUP($T16,DS!$A$2:$B$12,2,FALSE()),"")) | V16: =IF(OR($T16="",LEFT($T16,2)="99",LEFT($T16,2)="95"),"",TODAY()-MAX($E16,$H16:$P16)) | W16: =IF(AND($E16<>"",$I16="",$R16=""),IF(TODAY()-$E16>1,"⚑",""),"") | X16: =IF(AND($J16<>"",$K16="",$R16=""),IF(TODAY()-$J16>2,"⚑",""),"") | Y16: =IF(AND($G16<>"",$M16="",$R16=""),IF(AND($G16-TODAY()<=14,$G16>=TODAY()),"⚑",""),"") | Z16: =IF(AND($G16<>"",$P16="",$R16=""),IF(TODAY()>$G16,"⚑",""),"") | AA16: =IF(AND($E16<>"",$P16="",$R16=""),IF(TODAY()-MAX($E16,$H16,$M16,$S16)>7,"⚑",""),"") | AB16: =IF(OR($P16="",$G16=""),"",IF($P16<=$G16,"Có","Không")) | AC16: =IF(OR($P16="",$E16=""),"",$P16-$E16) | AD16: =IF($A16="","",COUNTIF(CASE!$B$3:$B$202,$A16)) | AE16: =IF(OR($I16="",$E16=""),"",$I16-$E16) | AF16: =IF(OR($K16="",$I16=""),"",$K16-$I16) | AG16: =IF(OR($L16="",$K16=""),"",$L16-$K16) | AH16: =IF(OR($M16="",$L16=""),"",$M16-$L16) | AI16: =IF(OR($P16="",$M16=""),"",$P16-$M16)
F17: =IF($E17="","",$E17+7*IFERROR(VLOOKUP($B17,DS!$K$2:$M$4,2,FALSE()),12)) | G17: =IF($E17="","",$E17+7*IFERROR(VLOOKUP($B17,DS!$K$2:$M$4,3,FALSE()),12)) | T17: =IF($A17="","",IF($R17<>"","95 Hủy/hoàn",IF($Q17<>"","99 Đóng",IF($P17<>"","90 Đã giao",IF($O17<>"","80 Đang giao",IF($N17<>"","70 Thông quan",IF($M17<>"","60 Đã xuất",IF($L17<>"","50 QC đạt",IF($K17<>"","40 NCC đã gửi",IF($I17<>"","30 Đã đặt NCC",IF($H17<>"","20 Đã xác nhận","10 Mới"))))))))))) | U17: =IF($T17="","",IFERROR(VLOOKUP($T17,DS!$A$2:$B$12,2,FALSE()),"")) | V17: =IF(OR($T17="",LEFT($T17,2)="99",LEFT($T17,2)="95"),"",TODAY()-MAX($E17,$H17:$P17)) | W17: =IF(AND($E17<>"",$I17="",$R17=""),IF(TODAY()-$E17>1,"⚑",""),"") | X17: =IF(AND($J17<>"",$K17="",$R17=""),IF(TODAY()-$J17>2,"⚑",""),"") | Y17: =IF(AND($G17<>"",$M17="",$R17=""),IF(AND($G17-TODAY()<=14,$G17>=TODAY()),"⚑",""),"") | Z17: =IF(AND($G17<>"",$P17="",$R17=""),IF(TODAY()>$G17,"⚑",""),"") | AA17: =IF(AND($E17<>"",$P17="",$R17=""),IF(TODAY()-MAX($E17,$H17,$M17,$S17)>7,"⚑",""),"") | AB17: =IF(OR($P17="",$G17=""),"",IF($P17<=$G17,"Có","Không")) | AC17: =IF(OR($P17="",$E17=""),"",$P17-$E17) | AD17: =IF($A17="","",COUNTIF(CASE!$B$3:$B$202,$A17)) | AE17: =IF(OR($I17="",$E17=""),"",$I17-$E17) | AF17: =IF(OR($K17="",$I17=""),"",$K17-$I17) | AG17: =IF(OR($L17="",$K17=""),"",$L17-$K17) | AH17: =IF(OR($M17="",$L17=""),"",$M17-$L17) | AI17: =IF(OR($P17="",$M17=""),"",$P17-$M17)
F18: =IF($E18="","",$E18+7*IFERROR(VLOOKUP($B18,DS!$K$2:$M$4,2,FALSE()),12)) | G18: =IF($E18="","",$E18+7*IFERROR(VLOOKUP($B18,DS!$K$2:$M$4,3,FALSE()),12)) | T18: =IF($A18="","",IF($R18<>"","95 Hủy/hoàn",IF($Q18<>"","99 Đóng",IF($P18<>"","90 Đã giao",IF($O18<>"","80 Đang giao",IF($N18<>"","70 Thông quan",IF($M18<>"","60 Đã xuất",IF($L18<>"","50 QC đạt",IF($K18<>"","40 NCC đã gửi",IF($I18<>"","30 Đã đặt NCC",IF($H18<>"","20 Đã xác nhận","10 Mới"))))))))))) | U18: =IF($T18="","",IFERROR(VLOOKUP($T18,DS!$A$2:$B$12,2,FALSE()),"")) | V18: =IF(OR($T18="",LEFT($T18,2)="99",LEFT($T18,2)="95"),"",TODAY()-MAX($E18,$H18:$P18)) | W18: =IF(AND($E18<>"",$I18="",$R18=""),IF(TODAY()-$E18>1,"⚑",""),"") | X18: =IF(AND($J18<>"",$K18="",$R18=""),IF(TODAY()-$J18>2,"⚑",""),"") | Y18: =IF(AND($G18<>"",$M18="",$R18=""),IF(AND($G18-TODAY()<=14,$G18>=TODAY()),"⚑",""),"") | Z18: =IF(AND($G18<>"",$P18="",$R18=""),IF(TODAY()>$G18,"⚑",""),"") | AA18: =IF(AND($E18<>"",$P18="",$R18=""),IF(TODAY()-MAX($E18,$H18,$M18,$S18)>7,"⚑",""),"") | AB18: =IF(OR($P18="",$G18=""),"",IF($P18<=$G18,"Có","Không")) | AC18: =IF(OR($P18="",$E18=""),"",$P18-$E18) | AD18: =IF($A18="","",COUNTIF(CASE!$B$3:$B$202,$A18)) | AE18: =IF(OR($I18="",$E18=""),"",$I18-$E18) | AF18: =IF(OR($K18="",$I18=""),"",$K18-$I18) | AG18: =IF(OR($L18="",$K18=""),"",$L18-$K18) | AH18: =IF(OR($M18="",$L18=""),"",$M18-$L18) | AI18: =IF(OR($P18="",$M18=""),"",$P18-$M18)
F19: =IF($E19="","",$E19+7*IFERROR(VLOOKUP($B19,DS!$K$2:$M$4,2,FALSE()),12)) | G19: =IF($E19="","",$E19+7*IFERROR(VLOOKUP($B19,DS!$K$2:$M$4,3,FALSE()),12)) | T19: =IF($A19="","",IF($R19<>"","95 Hủy/hoàn",IF($Q19<>"","99 Đóng",IF($P19<>"","90 Đã giao",IF($O19<>"","80 Đang giao",IF($N19<>"","70 Thông quan",IF($M19<>"","60 Đã xuất",IF($L19<>"","50 QC đạt",IF($K19<>"","40 NCC đã gửi",IF($I19<>"","30 Đã đặt NCC",IF($H19<>"","20 Đã xác nhận","10 Mới"))))))))))) | U19: =IF($T19="","",IFERROR(VLOOKUP($T19,DS!$A$2:$B$12,2,FALSE()),"")) | V19: =IF(OR($T19="",LEFT($T19,2)="99",LEFT($T19,2)="95"),"",TODAY()-MAX($E19,$H19:$P19)) | W19: =IF(AND($E19<>"",$I19="",$R19=""),IF(TODAY()-$E19>1,"⚑",""),"") | X19: =IF(AND($J19<>"",$K19="",$R19=""),IF(TODAY()-$J19>2,"⚑",""),"") | Y19: =IF(AND($G19<>"",$M19="",$R19=""),IF(AND($G19-TODAY()<=14,$G19>=TODAY()),"⚑",""),"") | Z19: =IF(AND($G19<>"",$P19="",$R19=""),IF(TODAY()>$G19,"⚑",""),"") | AA19: =IF(AND($E19<>"",$P19="",$R19=""),IF(TODAY()-MAX($E19,$H19,$M19,$S19)>7,"⚑",""),"") | AB19: =IF(OR($P19="",$G19=""),"",IF($P19<=$G19,"Có","Không")) | AC19: =IF(OR($P19="",$E19=""),"",$P19-$E19) | AD19: =IF($A19="","",COUNTIF(CASE!$B$3:$B$202,$A19)) | AE19: =IF(OR($I19="",$E19=""),"",$I19-$E19) | AF19: =IF(OR($K19="",$I19=""),"",$K19-$I19) | AG19: =IF(OR($L19="",$K19=""),"",$L19-$K19) | AH19: =IF(OR($M19="",$L19=""),"",$M19-$L19) | AI19: =IF(OR($P19="",$M19=""),"",$P19-$M19)
F20: =IF($E20="","",$E20+7*IFERROR(VLOOKUP($B20,DS!$K$2:$M$4,2,FALSE()),12)) | G20: =IF($E20="","",$E20+7*IFERROR(VLOOKUP($B20,DS!$K$2:$M$4,3,FALSE()),12)) | T20: =IF($A20="","",IF($R20<>"","95 Hủy/hoàn",IF($Q20<>"","99 Đóng",IF($P20<>"","90 Đã giao",IF($O20<>"","80 Đang giao",IF($N20<>"","70 Thông quan",IF($M20<>"","60 Đã xuất",IF($L20<>"","50 QC đạt",IF($K20<>"","40 NCC đã gửi",IF($I20<>"","30 Đã đặt NCC",IF($H20<>"","20 Đã xác nhận","10 Mới"))))))))))) | U20: =IF($T20="","",IFERROR(VLOOKUP($T20,DS!$A$2:$B$12,2,FALSE()),"")) | V20: =IF(OR($T20="",LEFT($T20,2)="99",LEFT($T20,2)="95"),"",TODAY()-MAX($E20,$H20:$P20)) | W20: =IF(AND($E20<>"",$I20="",$R20=""),IF(TODAY()-$E20>1,"⚑",""),"") | X20: =IF(AND($J20<>"",$K20="",$R20=""),IF(TODAY()-$J20>2,"⚑",""),"") | Y20: =IF(AND($G20<>"",$M20="",$R20=""),IF(AND($G20-TODAY()<=14,$G20>=TODAY()),"⚑",""),"") | Z20: =IF(AND($G20<>"",$P20="",$R20=""),IF(TODAY()>$G20,"⚑",""),"") | AA20: =IF(AND($E20<>"",$P20="",$R20=""),IF(TODAY()-MAX($E20,$H20,$M20,$S20)>7,"⚑",""),"") | AB20: =IF(OR($P20="",$G20=""),"",IF($P20<=$G20,"Có","Không")) | AC20: =IF(OR($P20="",$E20=""),"",$P20-$E20) | AD20: =IF($A20="","",COUNTIF(CASE!$B$3:$B$202,$A20)) | AE20: =IF(OR($I20="",$E20=""),"",$I20-$E20) | AF20: =IF(OR($K20="",$I20=""),"",$K20-$I20) | AG20: =IF(OR($L20="",$K20=""),"",$L20-$K20) | AH20: =IF(OR($M20="",$L20=""),"",$M20-$L20) | AI20: =IF(OR($P20="",$M20=""),"",$P20-$M20)
F21: =IF($E21="","",$E21+7*IFERROR(VLOOKUP($B21,DS!$K$2:$M$4,2,FALSE()),12)) | G21: =IF($E21="","",$E21+7*IFERROR(VLOOKUP($B21,DS!$K$2:$M$4,3,FALSE()),12)) | T21: =IF($A21="","",IF($R21<>"","95 Hủy/hoàn",IF($Q21<>"","99 Đóng",IF($P21<>"","90 Đã giao",IF($O21<>"","80 Đang giao",IF($N21<>"","70 Thông quan",IF($M21<>"","60 Đã xuất",IF($L21<>"","50 QC đạt",IF($K21<>"","40 NCC đã gửi",IF($I21<>"","30 Đã đặt NCC",IF($H21<>"","20 Đã xác nhận","10 Mới"))))))))))) | U21: =IF($T21="","",IFERROR(VLOOKUP($T21,DS!$A$2:$B$12,2,FALSE()),"")) | V21: =IF(OR($T21="",LEFT($T21,2)="99",LEFT($T21,2)="95"),"",TODAY()-MAX($E21,$H21:$P21)) | W21: =IF(AND($E21<>"",$I21="",$R21=""),IF(TODAY()-$E21>1,"⚑",""),"") | X21: =IF(AND($J21<>"",$K21="",$R21=""),IF(TODAY()-$J21>2,"⚑",""),"") | Y21: =IF(AND($G21<>"",$M21="",$R21=""),IF(AND($G21-TODAY()<=14,$G21>=TODAY()),"⚑",""),"") | Z21: =IF(AND($G21<>"",$P21="",$R21=""),IF(TODAY()>$G21,"⚑",""),"") | AA21: =IF(AND($E21<>"",$P21="",$R21=""),IF(TODAY()-MAX($E21,$H21,$M21,$S21)>7,"⚑",""),"") | AB21: =IF(OR($P21="",$G21=""),"",IF($P21<=$G21,"Có","Không")) | AC21: =IF(OR($P21="",$E21=""),"",$P21-$E21) | AD21: =IF($A21="","",COUNTIF(CASE!$B$3:$B$202,$A21)) | AE21: =IF(OR($I21="",$E21=""),"",$I21-$E21) | AF21: =IF(OR($K21="",$I21=""),"",$K21-$I21) | AG21: =IF(OR($L21="",$K21=""),"",$L21-$K21) | AH21: =IF(OR($M21="",$L21=""),"",$M21-$L21) | AI21: =IF(OR($P21="",$M21=""),"",$P21-$M21)
F22: =IF($E22="","",$E22+7*IFERROR(VLOOKUP($B22,DS!$K$2:$M$4,2,FALSE()),12)) | G22: =IF($E22="","",$E22+7*IFERROR(VLOOKUP($B22,DS!$K$2:$M$4,3,FALSE()),12)) | T22: =IF($A22="","",IF($R22<>"","95 Hủy/hoàn",IF($Q22<>"","99 Đóng",IF($P22<>"","90 Đã giao",IF($O22<>"","80 Đang giao",IF($N22<>"","70 Thông quan",IF($M22<>"","60 Đã xuất",IF($L22<>"","50 QC đạt",IF($K22<>"","40 NCC đã gửi",IF($I22<>"","30 Đã đặt NCC",IF($H22<>"","20 Đã xác nhận","10 Mới"))))))))))) | U22: =IF($T22="","",IFERROR(VLOOKUP($T22,DS!$A$2:$B$12,2,FALSE()),"")) | V22: =IF(OR($T22="",LEFT($T22,2)="99",LEFT($T22,2)="95"),"",TODAY()-MAX($E22,$H22:$P22)) | W22: =IF(AND($E22<>"",$I22="",$R22=""),IF(TODAY()-$E22>1,"⚑",""),"") | X22: =IF(AND($J22<>"",$K22="",$R22=""),IF(TODAY()-$J22>2,"⚑",""),"") | Y22: =IF(AND($G22<>"",$M22="",$R22=""),IF(AND($G22-TODAY()<=14,$G22>=TODAY()),"⚑",""),"") | Z22: =IF(AND($G22<>"",$P22="",$R22=""),IF(TODAY()>$G22,"⚑",""),"") | AA22: =IF(AND($E22<>"",$P22="",$R22=""),IF(TODAY()-MAX($E22,$H22,$M22,$S22)>7,"⚑",""),"") | AB22: =IF(OR($P22="",$G22=""),"",IF($P22<=$G22,"Có","Không")) | AC22: =IF(OR($P22="",$E22=""),"",$P22-$E22) | AD22: =IF($A22="","",COUNTIF(CASE!$B$3:$B$202,$A22)) | AE22: =IF(OR($I22="",$E22=""),"",$I22-$E22) | AF22: =IF(OR($K22="",$I22=""),"",$K22-$I22) | AG22: =IF(OR($L22="",$K22=""),"",$L22-$K22) | AH22: =IF(OR($M22="",$L22=""),"",$M22-$L22) | AI22: =IF(OR($P22="",$M22=""),"",$P22-$M22)
F23: =IF($E23="","",$E23+7*IFERROR(VLOOKUP($B23,DS!$K$2:$M$4,2,FALSE()),12)) | G23: =IF($E23="","",$E23+7*IFERROR(VLOOKUP($B23,DS!$K$2:$M$4,3,FALSE()),12)) | T23: =IF($A23="","",IF($R23<>"","95 Hủy/hoàn",IF($Q23<>"","99 Đóng",IF($P23<>"","90 Đã giao",IF($O23<>"","80 Đang giao",IF($N23<>"","70 Thông quan",IF($M23<>"","60 Đã xuất",IF($L23<>"","50 QC đạt",IF($K23<>"","40 NCC đã gửi",IF($I23<>"","30 Đã đặt NCC",IF($H23<>"","20 Đã xác nhận","10 Mới"))))))))))) | U23: =IF($T23="","",IFERROR(VLOOKUP($T23,DS!$A$2:$B$12,2,FALSE()),"")) | V23: =IF(OR($T23="",LEFT($T23,2)="99",LEFT($T23,2)="95"),"",TODAY()-MAX($E23,$H23:$P23)) | W23: =IF(AND($E23<>"",$I23="",$R23=""),IF(TODAY()-$E23>1,"⚑",""),"") | X23: =IF(AND($J23<>"",$K23="",$R23=""),IF(TODAY()-$J23>2,"⚑",""),"") | Y23: =IF(AND($G23<>"",$M23="",$R23=""),IF(AND($G23-TODAY()<=14,$G23>=TODAY()),"⚑",""),"") | Z23: =IF(AND($G23<>"",$P23="",$R23=""),IF(TODAY()>$G23,"⚑",""),"") | AA23: =IF(AND($E23<>"",$P23="",$R23=""),IF(TODAY()-MAX($E23,$H23,$M23,$S23)>7,"⚑",""),"") | AB23: =IF(OR($P23="",$G23=""),"",IF($P23<=$G23,"Có","Không")) | AC23: =IF(OR($P23="",$E23=""),"",$P23-$E23) | AD23: =IF($A23="","",COUNTIF(CASE!$B$3:$B$202,$A23)) | AE23: =IF(OR($I23="",$E23=""),"",$I23-$E23) | AF23: =IF(OR($K23="",$I23=""),"",$K23-$I23) | AG23: =IF(OR($L23="",$K23=""),"",$L23-$K23) | AH23: =IF(OR($M23="",$L23=""),"",$M23-$L23) | AI23: =IF(OR($P23="",$M23=""),"",$P23-$M23)
F24: =IF($E24="","",$E24+7*IFERROR(VLOOKUP($B24,DS!$K$2:$M$4,2,FALSE()),12)) | G24: =IF($E24="","",$E24+7*IFERROR(VLOOKUP($B24,DS!$K$2:$M$4,3,FALSE()),12)) | T24: =IF($A24="","",IF($R24<>"","95 Hủy/hoàn",IF($Q24<>"","99 Đóng",IF($P24<>"","90 Đã giao",IF($O24<>"","80 Đang giao",IF($N24<>"","70 Thông quan",IF($M24<>"","60 Đã xuất",IF($L24<>"","50 QC đạt",IF($K24<>"","40 NCC đã gửi",IF($I24<>"","30 Đã đặt NCC",IF($H24<>"","20 Đã xác nhận","10 Mới"))))))))))) | U24: =IF($T24="","",IFERROR(VLOOKUP($T24,DS!$A$2:$B$12,2,FALSE()),"")) | V24: =IF(OR($T24="",LEFT($T24,2)="99",LEFT($T24,2)="95"),"",TODAY()-MAX($E24,$H24:$P24)) | W24: =IF(AND($E24<>"",$I24="",$R24=""),IF(TODAY()-$E24>1,"⚑",""),"") | X24: =IF(AND($J24<>"",$K24="",$R24=""),IF(TODAY()-$J24>2,"⚑",""),"") | Y24: =IF(AND($G24<>"",$M24="",$R24=""),IF(AND($G24-TODAY()<=14,$G24>=TODAY()),"⚑",""),"") | Z24: =IF(AND($G24<>"",$P24="",$R24=""),IF(TODAY()>$G24,"⚑",""),"") | AA24: =IF(AND($E24<>"",$P24="",$R24=""),IF(TODAY()-MAX($E24,$H24,$M24,$S24)>7,"⚑",""),"") | AB24: =IF(OR($P24="",$G24=""),"",IF($P24<=$G24,"Có","Không")) | AC24: =IF(OR($P24="",$E24=""),"",$P24-$E24) | AD24: =IF($A24="","",COUNTIF(CASE!$B$3:$B$202,$A24)) | AE24: =IF(OR($I24="",$E24=""),"",$I24-$E24) | AF24: =IF(OR($K24="",$I24=""),"",$K24-$I24) | AG24: =IF(OR($L24="",$K24=""),"",$L24-$K24) | AH24: =IF(OR($M24="",$L24=""),"",$M24-$L24) | AI24: =IF(OR($P24="",$M24=""),"",$P24-$M24)
F25: =IF($E25="","",$E25+7*IFERROR(VLOOKUP($B25,DS!$K$2:$M$4,2,FALSE()),12)) | G25: =IF($E25="","",$E25+7*IFERROR(VLOOKUP($B25,DS!$K$2:$M$4,3,FALSE()),12)) | T25: =IF($A25="","",IF($R25<>"","95 Hủy/hoàn",IF($Q25<>"","99 Đóng",IF($P25<>"","90 Đã giao",IF($O25<>"","80 Đang giao",IF($N25<>"","70 Thông quan",IF($M25<>"","60 Đã xuất",IF($L25<>"","50 QC đạt",IF($K25<>"","40 NCC đã gửi",IF($I25<>"","30 Đã đặt NCC",IF($H25<>"","20 Đã xác nhận","10 Mới"))))))))))) | U25: =IF($T25="","",IFERROR(VLOOKUP($T25,DS!$A$2:$B$12,2,FALSE()),"")) | V25: =IF(OR($T25="",LEFT($T25,2)="99",LEFT($T25,2)="95"),"",TODAY()-MAX($E25,$H25:$P25)) | W25: =IF(AND($E25<>"",$I25="",$R25=""),IF(TODAY()-$E25>1,"⚑",""),"") | X25: =IF(AND($J25<>"",$K25="",$R25=""),IF(TODAY()-$J25>2,"⚑",""),"") | Y25: =IF(AND($G25<>"",$M25="",$R25=""),IF(AND($G25-TODAY()<=14,$G25>=TODAY()),"⚑",""),"") | Z25: =IF(AND($G25<>"",$P25="",$R25=""),IF(TODAY()>$G25,"⚑",""),"") | AA25: =IF(AND($E25<>"",$P25="",$R25=""),IF(TODAY()-MAX($E25,$H25,$M25,$S25)>7,"⚑",""),"") | AB25: =IF(OR($P25="",$G25=""),"",IF($P25<=$G25,"Có","Không")) | AC25: =IF(OR($P25="",$E25=""),"",$P25-$E25) | AD25: =IF($A25="","",COUNTIF(CASE!$B$3:$B$202,$A25)) | AE25: =IF(OR($I25="",$E25=""),"",$I25-$E25) | AF25: =IF(OR($K25="",$I25=""),"",$K25-$I25) | AG25: =IF(OR($L25="",$K25=""),"",$L25-$K25) | AH25: =IF(OR($M25="",$L25=""),"",$M25-$L25) | AI25: =IF(OR($P25="",$M25=""),"",$P25-$M25)
F26: =IF($E26="","",$E26+7*IFERROR(VLOOKUP($B26,DS!$K$2:$M$4,2,FALSE()),12)) | G26: =IF($E26="","",$E26+7*IFERROR(VLOOKUP($B26,DS!$K$2:$M$4,3,FALSE()),12)) | T26: =IF($A26="","",IF($R26<>"","95 Hủy/hoàn",IF($Q26<>"","99 Đóng",IF($P26<>"","90 Đã giao",IF($O26<>"","80 Đang giao",IF($N26<>"","70 Thông quan",IF($M26<>"","60 Đã xuất",IF($L26<>"","50 QC đạt",IF($K26<>"","40 NCC đã gửi",IF($I26<>"","30 Đã đặt NCC",IF($H26<>"","20 Đã xác nhận","10 Mới"))))))))))) | U26: =IF($T26="","",IFERROR(VLOOKUP($T26,DS!$A$2:$B$12,2,FALSE()),"")) | V26: =IF(OR($T26="",LEFT($T26,2)="99",LEFT($T26,2)="95"),"",TODAY()-MAX($E26,$H26:$P26)) | W26: =IF(AND($E26<>"",$I26="",$R26=""),IF(TODAY()-$E26>1,"⚑",""),"") | X26: =IF(AND($J26<>"",$K26="",$R26=""),IF(TODAY()-$J26>2,"⚑",""),"") | Y26: =IF(AND($G26<>"",$M26="",$R26=""),IF(AND($G26-TODAY()<=14,$G26>=TODAY()),"⚑",""),"") | Z26: =IF(AND($G26<>"",$P26="",$R26=""),IF(TODAY()>$G26,"⚑",""),"") | AA26: =IF(AND($E26<>"",$P26="",$R26=""),IF(TODAY()-MAX($E26,$H26,$M26,$S26)>7,"⚑",""),"") | AB26: =IF(OR($P26="",$G26=""),"",IF($P26<=$G26,"Có","Không")) | AC26: =IF(OR($P26="",$E26=""),"",$P26-$E26) | AD26: =IF($A26="","",COUNTIF(CASE!$B$3:$B$202,$A26)) | AE26: =IF(OR($I26="",$E26=""),"",$I26-$E26) | AF26: =IF(OR($K26="",$I26=""),"",$K26-$I26) | AG26: =IF(OR($L26="",$K26=""),"",$L26-$K26) | AH26: =IF(OR($M26="",$L26=""),"",$M26-$L26) | AI26: =IF(OR($P26="",$M26=""),"",$P26-$M26)
... F402: =IF($E402="","",$E402+7*IFERROR(VLOOKUP($B402,DS!$K$2:$M$4,2,FALSE()),12)) | G402: =IF($E402="","",$E402+7*IFERROR(VLOOKUP($B402,DS!$K$2:$M$4,3,FALSE()),12)) | T402: =IF($A402="","",IF($R402<>"","95 Hủy/hoàn",IF($Q402<>"","99 Đóng",IF($P402<>"","90 Đã giao",IF($O402<>"","80 Đang giao",IF($N402<>"","70 Thông quan",IF($M402<>"","60 Đã xuất",IF($L402<>"","50 QC đạt",IF($K402<>"","40 NCC đã gửi",IF($I402<>"","30 Đã đặt NCC",IF($H402<>"","20 Đã xác nhận","10 Mới"))))))))))) | U402: =IF($T402="","",IFERROR(VLOOKUP($T402,DS!$A$2:$B$12,2,FALSE()),"")) | V402: =IF(OR($T402="",LEFT($T402,2)="99",LEFT($T402,2)="95"),"",TODAY()-MAX($E402,$H402:$P402)) | W402: =IF(AND($E402<>"",$I402="",$R402=""),IF(TODAY()-$E402>1,"⚑",""),"") | X402: =IF(AND($J402<>"",$K402="",$R402=""),IF(TODAY()-$J402>2,"⚑",""),"") | Y402: =IF(AND($G402<>"",$M402="",$R402=""),IF(AND($G402-TODAY()<=14,$G402>=TODAY()),"⚑",""),"") | Z402: =IF(AND($G402<>"",$P402="",$R402=""),IF(TODAY()>$G402,"⚑",""),"") | AA402: =IF(AND($E402<>"",$P402="",$R402=""),IF(TODAY()-MAX($E402,$H402,$M402,$S402)>7,"⚑",""),"") | AB402: =IF(OR($P402="",$G402=""),"",IF($P402<=$G402,"Có","Không")) | AC402: =IF(OR($P402="",$E402=""),"",$P402-$E402) | AD402: =IF($A402="","",COUNTIF(CASE!$B$3:$B$202,$A402)) | AE402: =IF(OR($I402="",$E402=""),"",$I402-$E402) | AF402: =IF(OR($K402="",$I402=""),"",$K402-$I402) | AG402: =IF(OR($L402="",$K402=""),"",$L402-$K402) | AH402: =IF(OR($M402="",$L402=""),"",$M402-$L402) | AI402: =IF(OR($P402="",$M402=""),"",$P402-$M402)

Sheet CASE
A1: SOP-B · Theo dõi case hậu mãi — mỗi case một dòng · đóng case phải có nguyên nhân gốc
A2: Mã case | B2: Mã đơn | C2: Loại | D2: Kênh | E2: Mở lúc | F2: Phản hồi đầu lúc | G2: Đủ bằng chứng | H2: Giải pháp | I2: Đền bù / hoàn (A$) | J2: Cấp duyệt cần | K2: Người duyệt | L2: Đúng cấp? | M2: Thực thi xong | N2: Ngày hoàn tiền | O2: Đóng case | P2: Nguyên nhân gốc | Q2: Thu hồi từ | R2: Số thu hồi (A$) | S2: Chi phí ròng (A$) | T2: Giờ phản hồi | U2: Số ngày mở | V2: ⚑ Phản hồi >24h | W2: ⚑ Mở >7 ngày | X2: ⚑ Duyệt sai cấp | Y2: Ghi chú (không ghi dữ liệu cá nhân)
A3: DEMO-C01 | B3: DEMO-1003 | C3: C4 Thiếu kiện/phụ kiện | D3: Email | E3: 46298.375 | F3: 46298.458 | G3: 46298 | H3: R2 Gửi bù | I3: 15 | J3: =IF($I3="","",IF(OR($I3>150,$H3="R4 Hoàn 100%"),"CEO",IF($I3>50,"OPS","CX"))) -> CX | K3: CX | L3: =IF(OR($J3="",$K3=""),"",IF(MATCH($K3,DS!$H$2:$H$4,0)>=MATCH($J3,DS!$H$2:$H$4,0),"✓","✗")) -> ✓ | P3: RC-PACK | Q3: NCC | S3: =IF($A3="","",N($I3)-N($R3)) -> 15 | T3: =IF(OR($E3="",$F3=""),"",ROUND(($F3-$E3)*24,1)) -> 2 | U3: =IF($E3="","",INT(IF($O3="",NOW(),$O3)-$E3)) -> 0 | V3: =IF($E3="","",IF($F3="",IF((NOW()-$E3)*24>24,"⚑",""),IF(($F3-$E3)*24>24,"⚑",""))) | W3: =IF(OR($E3="",$O3<>""),"",IF(NOW()-$E3>7,"⚑","")) | X3: =IF($L3="✗","⚑","")
A4: DEMO-C02 | B4: DEMO-1002 | C4: C3 Hư hỏng | D4: Form web | E4: 46270.333 | F4: 46270.417 | G4: 46271 | H4: R4 Hoàn một phần | I4: 72 | J4: =IF($I4="","",IF(OR($I4>150,$H4="R4 Hoàn 100%"),"CEO",IF($I4>50,"OPS","CX"))) -> OPS | K4: OPS | L4: =IF(OR($J4="",$K4=""),"",IF(MATCH($K4,DS!$H$2:$H$4,0)>=MATCH($J4,DS!$H$2:$H$4,0),"✓","✗")) -> ✓ | M4: 46272 | N4: 46272 | O4: 46273 | P4: RC-LAST | Q4: Hãng giao | R4: 72 | S4: =IF($A4="","",N($I4)-N($R4)) -> 0 | T4: =IF(OR($E4="",$F4=""),"",ROUND(($F4-$E4)*24,1)) -> 2 | U4: =IF($E4="","",INT(IF($O4="",NOW(),$O4)-$E4)) -> 2 | V4: =IF($E4="","",IF($F4="",IF((NOW()-$E4)*24>24,"⚑",""),IF(($F4-$E4)*24>24,"⚑",""))) | W4: =IF(OR($E4="",$O4<>""),"",IF(NOW()-$E4>7,"⚑","")) | X4: =IF($L4="✗","⚑","")
A5: DEMO-C03 | B5: DEMO-1012 | C5: C1 Hủy đơn | D5: Email | E5: 46269.583 | F5: 46269.625 | G5: 46269 | H5: R4 Hoàn 100% | I5: 650 | J5: =IF($I5="","",IF(OR($I5>150,$H5="R4 Hoàn 100%"),"CEO",IF($I5>50,"OPS","CX"))) -> CEO | K5: CEO | L5: =IF(OR($J5="",$K5=""),"",IF(MATCH($K5,DS!$H$2:$H$4,0)>=MATCH($J5,DS!$H$2:$H$4,0),"✓","✗")) -> ✓ | M5: 46270 | N5: 46270 | O5: 46270 | P5: RC-CUST | S5: =IF($A5="","",N($I5)-N($R5)) -> 650 | T5: =IF(OR($E5="",$F5=""),"",ROUND(($F5-$E5)*24,1)) -> 1 | U5: =IF($E5="","",INT(IF($O5="",NOW(),$O5)-$E5)) -> 0 | V5: =IF($E5="","",IF($F5="",IF((NOW()-$E5)*24>24,"⚑",""),IF(($F5-$E5)*24>24,"⚑",""))) | W5: =IF(OR($E5="",$O5<>""),"",IF(NOW()-$E5>7,"⚑","")) | X5: =IF($L5="✗","⚑","")
A6: DEMO-C04 | B6: DEMO-1011 | C6: C2 Trễ hạn | D6: Messenger | E6: 46290.417 | F6: 46291.667 | G6: 46290 | H6: R4 Tín dụng | I6: 49 | J6: =IF($I6="","",IF(OR($I6>150,$H6="R4 Hoàn 100%"),"CEO",IF($I6>50,"OPS","CX"))) -> CX | K6: CX | L6: =IF(OR($J6="",$K6=""),"",IF(MATCH($K6,DS!$H$2:$H$4,0)>=MATCH($J6,DS!$H$2:$H$4,0),"✓","✗")) -> ✓ | P6: RC-NCC | S6: =IF($A6="","",N($I6)-N($R6)) -> 49 | T6: =IF(OR($E6="",$F6=""),"",ROUND(($F6-$E6)*24,1)) -> 30 | U6: =IF($E6="","",INT(IF($O6="",NOW(),$O6)-$E6)) -> 8 | V6: =IF($E6="","",IF($F6="",IF((NOW()-$E6)*24>24,"⚑",""),IF(($F6-$E6)*24>24,"⚑",""))) -> ⚑ | W6: =IF(OR($E6="",$O6<>""),"",IF(NOW()-$E6>7,"⚑","")) -> ⚑ | X6: =IF($L6="✗","⚑","")
A7: DEMO-C05 | B7: DEMO-1001 | C7: C8 Bảo hành | D7: WhatsApp | E7: 46289.375 | F7: 46289.396 | G7: 46290 | H7: R1 Sửa | I7: 120 | J7: =IF($I7="","",IF(OR($I7>150,$H7="R4 Hoàn 100%"),"CEO",IF($I7>50,"OPS","CX"))) -> OPS | K7: CX | L7: =IF(OR($J7="",$K7=""),"",IF(MATCH($K7,DS!$H$2:$H$4,0)>=MATCH($J7,DS!$H$2:$H$4,0),"✓","✗")) -> ✗ | M7: 46293 | O7: 46294 | P7: RC-NCC | Q7: NCC | R7: 120 | S7: =IF($A7="","",N($I7)-N($R7)) -> 0 | T7: =IF(OR($E7="",$F7=""),"",ROUND(($F7-$E7)*24,1)) -> 0.5 | U7: =IF($E7="","",INT(IF($O7="",NOW(),$O7)-$E7)) -> 4 | V7: =IF($E7="","",IF($F7="",IF((NOW()-$E7)*24>24,"⚑",""),IF(($F7-$E7)*24>24,"⚑",""))) | W7: =IF(OR($E7="",$O7<>""),"",IF(NOW()-$E7>7,"⚑","")) | X7: =IF($L7="✗","⚑","") -> ⚑
J8: =IF($I8="","",IF(OR($I8>150,$H8="R4 Hoàn 100%"),"CEO",IF($I8>50,"OPS","CX"))) | L8: =IF(OR($J8="",$K8=""),"",IF(MATCH($K8,DS!$H$2:$H$4,0)>=MATCH($J8,DS!$H$2:$H$4,0),"✓","✗")) | S8: =IF($A8="","",N($I8)-N($R8)) | T8: =IF(OR($E8="",$F8=""),"",ROUND(($F8-$E8)*24,1)) | U8: =IF($E8="","",INT(IF($O8="",NOW(),$O8)-$E8)) | V8: =IF($E8="","",IF($F8="",IF((NOW()-$E8)*24>24,"⚑",""),IF(($F8-$E8)*24>24,"⚑",""))) | W8: =IF(OR($E8="",$O8<>""),"",IF(NOW()-$E8>7,"⚑","")) | X8: =IF($L8="✗","⚑","")
J9: =IF($I9="","",IF(OR($I9>150,$H9="R4 Hoàn 100%"),"CEO",IF($I9>50,"OPS","CX"))) | L9: =IF(OR($J9="",$K9=""),"",IF(MATCH($K9,DS!$H$2:$H$4,0)>=MATCH($J9,DS!$H$2:$H$4,0),"✓","✗")) | S9: =IF($A9="","",N($I9)-N($R9)) | T9: =IF(OR($E9="",$F9=""),"",ROUND(($F9-$E9)*24,1)) | U9: =IF($E9="","",INT(IF($O9="",NOW(),$O9)-$E9)) | V9: =IF($E9="","",IF($F9="",IF((NOW()-$E9)*24>24,"⚑",""),IF(($F9-$E9)*24>24,"⚑",""))) | W9: =IF(OR($E9="",$O9<>""),"",IF(NOW()-$E9>7,"⚑","")) | X9: =IF($L9="✗","⚑","")
J10: =IF($I10="","",IF(OR($I10>150,$H10="R4 Hoàn 100%"),"CEO",IF($I10>50,"OPS","CX"))) | L10: =IF(OR($J10="",$K10=""),"",IF(MATCH($K10,DS!$H$2:$H$4,0)>=MATCH($J10,DS!$H$2:$H$4,0),"✓","✗")) | S10: =IF($A10="","",N($I10)-N($R10)) | T10: =IF(OR($E10="",$F10=""),"",ROUND(($F10-$E10)*24,1)) | U10: =IF($E10="","",INT(IF($O10="",NOW(),$O10)-$E10)) | V10: =IF($E10="","",IF($F10="",IF((NOW()-$E10)*24>24,"⚑",""),IF(($F10-$E10)*24>24,"⚑",""))) | W10: =IF(OR($E10="",$O10<>""),"",IF(NOW()-$E10>7,"⚑","")) | X10: =IF($L10="✗","⚑","")
J11: =IF($I11="","",IF(OR($I11>150,$H11="R4 Hoàn 100%"),"CEO",IF($I11>50,"OPS","CX"))) | L11: =IF(OR($J11="",$K11=""),"",IF(MATCH($K11,DS!$H$2:$H$4,0)>=MATCH($J11,DS!$H$2:$H$4,0),"✓","✗")) | S11: =IF($A11="","",N($I11)-N($R11)) | T11: =IF(OR($E11="",$F11=""),"",ROUND(($F11-$E11)*24,1)) | U11: =IF($E11="","",INT(IF($O11="",NOW(),$O11)-$E11)) | V11: =IF($E11="","",IF($F11="",IF((NOW()-$E11)*24>24,"⚑",""),IF(($F11-$E11)*24>24,"⚑",""))) | W11: =IF(OR($E11="",$O11<>""),"",IF(NOW()-$E11>7,"⚑","")) | X11: =IF($L11="✗","⚑","")
J12: =IF($I12="","",IF(OR($I12>150,$H12="R4 Hoàn 100%"),"CEO",IF($I12>50,"OPS","CX"))) | L12: =IF(OR($J12="",$K12=""),"",IF(MATCH($K12,DS!$H$2:$H$4,0)>=MATCH($J12,DS!$H$2:$H$4,0),"✓","✗")) | S12: =IF($A12="","",N($I12)-N($R12)) | T12: =IF(OR($E12="",$F12=""),"",ROUND(($F12-$E12)*24,1)) | U12: =IF($E12="","",INT(IF($O12="",NOW(),$O12)-$E12)) | V12: =IF($E12="","",IF($F12="",IF((NOW()-$E12)*24>24,"⚑",""),IF(($F12-$E12)*24>24,"⚑",""))) | W12: =IF(OR($E12="",$O12<>""),"",IF(NOW()-$E12>7,"⚑","")) | X12: =IF($L12="✗","⚑","")
J13: =IF($I13="","",IF(OR($I13>150,$H13="R4 Hoàn 100%"),"CEO",IF($I13>50,"OPS","CX"))) | L13: =IF(OR($J13="",$K13=""),"",IF(MATCH($K13,DS!$H$2:$H$4,0)>=MATCH($J13,DS!$H$2:$H$4,0),"✓","✗")) | S13: =IF($A13="","",N($I13)-N($R13)) | T13: =IF(OR($E13="",$F13=""),"",ROUND(($F13-$E13)*24,1)) | U13: =IF($E13="","",INT(IF($O13="",NOW(),$O13)-$E13)) | V13: =IF($E13="","",IF($F13="",IF((NOW()-$E13)*24>24,"⚑",""),IF(($F13-$E13)*24>24,"⚑",""))) | W13: =IF(OR($E13="",$O13<>""),"",IF(NOW()-$E13>7,"⚑","")) | X13: =IF($L13="✗","⚑","")
J14: =IF($I14="","",IF(OR($I14>150,$H14="R4 Hoàn 100%"),"CEO",IF($I14>50,"OPS","CX"))) | L14: =IF(OR($J14="",$K14=""),"",IF(MATCH($K14,DS!$H$2:$H$4,0)>=MATCH($J14,DS!$H$2:$H$4,0),"✓","✗")) | S14: =IF($A14="","",N($I14)-N($R14)) | T14: =IF(OR($E14="",$F14=""),"",ROUND(($F14-$E14)*24,1)) | U14: =IF($E14="","",INT(IF($O14="",NOW(),$O14)-$E14)) | V14: =IF($E14="","",IF($F14="",IF((NOW()-$E14)*24>24,"⚑",""),IF(($F14-$E14)*24>24,"⚑",""))) | W14: =IF(OR($E14="",$O14<>""),"",IF(NOW()-$E14>7,"⚑","")) | X14: =IF($L14="✗","⚑","")
J15: =IF($I15="","",IF(OR($I15>150,$H15="R4 Hoàn 100%"),"CEO",IF($I15>50,"OPS","CX"))) | L15: =IF(OR($J15="",$K15=""),"",IF(MATCH($K15,DS!$H$2:$H$4,0)>=MATCH($J15,DS!$H$2:$H$4,0),"✓","✗")) | S15: =IF($A15="","",N($I15)-N($R15)) | T15: =IF(OR($E15="",$F15=""),"",ROUND(($F15-$E15)*24,1)) | U15: =IF($E15="","",INT(IF($O15="",NOW(),$O15)-$E15)) | V15: =IF($E15="","",IF($F15="",IF((NOW()-$E15)*24>24,"⚑",""),IF(($F15-$E15)*24>24,"⚑",""))) | W15: =IF(OR($E15="",$O15<>""),"",IF(NOW()-$E15>7,"⚑","")) | X15: =IF($L15="✗","⚑","")
J16: =IF($I16="","",IF(OR($I16>150,$H16="R4 Hoàn 100%"),"CEO",IF($I16>50,"OPS","CX"))) | L16: =IF(OR($J16="",$K16=""),"",IF(MATCH($K16,DS!$H$2:$H$4,0)>=MATCH($J16,DS!$H$2:$H$4,0),"✓","✗")) | S16: =IF($A16="","",N($I16)-N($R16)) | T16: =IF(OR($E16="",$F16=""),"",ROUND(($F16-$E16)*24,1)) | U16: =IF($E16="","",INT(IF($O16="",NOW(),$O16)-$E16)) | V16: =IF($E16="","",IF($F16="",IF((NOW()-$E16)*24>24,"⚑",""),IF(($F16-$E16)*24>24,"⚑",""))) | W16: =IF(OR($E16="",$O16<>""),"",IF(NOW()-$E16>7,"⚑","")) | X16: =IF($L16="✗","⚑","")
J17: =IF($I17="","",IF(OR($I17>150,$H17="R4 Hoàn 100%"),"CEO",IF($I17>50,"OPS","CX"))) | L17: =IF(OR($J17="",$K17=""),"",IF(MATCH($K17,DS!$H$2:$H$4,0)>=MATCH($J17,DS!$H$2:$H$4,0),"✓","✗")) | S17: =IF($A17="","",N($I17)-N($R17)) | T17: =IF(OR($E17="",$F17=""),"",ROUND(($F17-$E17)*24,1)) | U17: =IF($E17="","",INT(IF($O17="",NOW(),$O17)-$E17)) | V17: =IF($E17="","",IF($F17="",IF((NOW()-$E17)*24>24,"⚑",""),IF(($F17-$E17)*24>24,"⚑",""))) | W17: =IF(OR($E17="",$O17<>""),"",IF(NOW()-$E17>7,"⚑","")) | X17: =IF($L17="✗","⚑","")
J18: =IF($I18="","",IF(OR($I18>150,$H18="R4 Hoàn 100%"),"CEO",IF($I18>50,"OPS","CX"))) | L18: =IF(OR($J18="",$K18=""),"",IF(MATCH($K18,DS!$H$2:$H$4,0)>=MATCH($J18,DS!$H$2:$H$4,0),"✓","✗")) | S18: =IF($A18="","",N($I18)-N($R18)) | T18: =IF(OR($E18="",$F18=""),"",ROUND(($F18-$E18)*24,1)) | U18: =IF($E18="","",INT(IF($O18="",NOW(),$O18)-$E18)) | V18: =IF($E18="","",IF($F18="",IF((NOW()-$E18)*24>24,"⚑",""),IF(($F18-$E18)*24>24,"⚑",""))) | W18: =IF(OR($E18="",$O18<>""),"",IF(NOW()-$E18>7,"⚑","")) | X18: =IF($L18="✗","⚑","")
J19: =IF($I19="","",IF(OR($I19>150,$H19="R4 Hoàn 100%"),"CEO",IF($I19>50,"OPS","CX"))) | L19: =IF(OR($J19="",$K19=""),"",IF(MATCH($K19,DS!$H$2:$H$4,0)>=MATCH($J19,DS!$H$2:$H$4,0),"✓","✗")) | S19: =IF($A19="","",N($I19)-N($R19)) | T19: =IF(OR($E19="",$F19=""),"",ROUND(($F19-$E19)*24,1)) | U19: =IF($E19="","",INT(IF($O19="",NOW(),$O19)-$E19)) | V19: =IF($E19="","",IF($F19="",IF((NOW()-$E19)*24>24,"⚑",""),IF(($F19-$E19)*24>24,"⚑",""))) | W19: =IF(OR($E19="",$O19<>""),"",IF(NOW()-$E19>7,"⚑","")) | X19: =IF($L19="✗","⚑","")
... J202: =IF($I202="","",IF(OR($I202>150,$H202="R4 Hoàn 100%"),"CEO",IF($I202>50,"OPS","CX"))) | L202: =IF(OR($J202="",$K202=""),"",IF(MATCH($K202,DS!$H$2:$H$4,0)>=MATCH($J202,DS!$H$2:$H$4,0),"✓","✗")) | S202: =IF($A202="","",N($I202)-N($R202)) | T202: =IF(OR($E202="",$F202=""),"",ROUND(($F202-$E202)*24,1)) | U202: =IF($E202="","",INT(IF($O202="",NOW(),$O202)-$E202)) | V202: =IF($E202="","",IF($F202="",IF((NOW()-$E202)*24>24,"⚑",""),IF(($F202-$E202)*24>24,"⚑",""))) | W202: =IF(OR($E202="",$O202<>""),"",IF(NOW()-$E202>7,"⚑","")) | X202: =IF($L202="✗","⚑","")

Sheet DS
A1: Trạng thái | B1: Chủ trì | C1: Bằng chứng để vào | E1: Loại case | F1: Luồng | G1: Giải pháp | H1: Cấp duyệt | I1: Nguyên nhân gốc | K1: Thị trường | L1: ETA min (tuần) | M1: ETA max (tuần) | O1: Kênh
A2: 10 Mới | B2: CX | C2: Đã thanh toán | E2: C1 Hủy đơn | F2: B1 | G2: R1 Sửa | H2: CX | I2: RC-NCC | K2: AU | L2: 8 | M2: 12 | O2: Email
A3: 20 Đã xác nhận | B3: SRC | C3: Email xác nhận + ETA | E3: C2 Trễ hạn | F3: B1 | G3: R2 Gửi bù | H3: OPS | I3: RC-PACK | K3: SG | L3: 5 | M3: 8 | O3: Form web
A4: 30 Đã đặt NCC | B4: SRC | C4: Có mã PO | E4: C3 Hư hỏng | F4: B1·B2 | G4: R3 Đổi mới | H4: CEO | I4: RC-QC | K4: NZ | L4: 10 | M4: 14 | O4: Messenger
A5: 40 NCC đã gửi | B5: SRC | C5: Vận đơn nội địa | E5: C4 Thiếu kiện/phụ kiện | F5: B1 | G5: R4 Hoàn một phần | I5: RC-FWD | O5: Instagram
A6: 50 QC đạt | B6: LOG | C6: Ảnh QC kho gom | E6: C5 Sai hàng/khác mô tả | F6: B1·B2 | G6: R4 Hoàn 100% | H6: Mức duyệt: ≤ A$50 CX · 51–150 OPS · > 150 hoặc hoàn 100% CEO | I6: RC-LAST | K6: Khung ETA = chính sách đã công bố (chỉnh tại L2:M4). NZ chưa bán, để sẵn. | O6: WhatsApp
A7: 60 Đã xuất | B7: LOG | C7: Lượt quét thật | E7: C6 Đổi ý | F7: B2 | G7: R4 Tín dụng | I7: RC-LIST | O7: Điện thoại
A8: 70 Thông quan | B8: LOG | C8: Tới cảng / hải quan | E8: C7 Chargeback | F8: B3 | G8: R5 Thu hồi | I8: RC-CX | O8: Cổng thanh toán
A9: 80 Đang giao | B9: LOG | C9: Hãng giao nhận hàng | E9: C8 Bảo hành | F9: B1 | G9: Không bồi thường | I9: RC-CUST
A10: 90 Đã giao | B10: CX | C10: POD / ảnh giao
A11: 95 Hủy/hoàn | B11: – | C11: Đã hoàn tiền
A12: 99 Đóng | B12: – | C12: D+14 không case
