Workbook

Sheet HUONG_DAN
B2: [BRAND] Source of Truth
B3: Sổ tay | C3: https://doanngocmyy.github.io/brand-operating-handbook/docs/index.html
B4: Ô trắng | C4: Nhập tay. Chỉ nhập ngày khi đã có BẰNG CHỨNG (mã PO, ảnh QC, lượt quét thật, POD).
B5: Cột tiêu đề xám | C5: Tự tính bằng một công thức ở dòng 3 (ARRAYFORMULA). Không gõ vào các cột này.
B6: Màu tiêu đề | C6: Vị trí nhập: xanh dương CX · xanh lá SRC · xanh ngọc LOG · nâu OPS · tím FIN · xám tự tính.
B7: Họp 09:00 | C7: DASHBOARD → “Cờ SLA đang bật”. Lọc từng cột ⚑ ở DON/CASE, giao người xử lý trong ngày.
B8: Thứ Sáu | C8: OPS chụp DASHBOARD vào báo cáo tuần. Đếm case theo nguyên nhân gốc.
B9: Dữ liệu | C9: KHÔNG ghi tên, email, SĐT, địa chỉ khách. Mã đơn là khóa nối. Chi phí FIN và danh tính NCC để file riêng.
B10: Phân quyền | C10: Khi có nhiều người: chia sẻ theo vị trí, khóa (Protect) các cột xám và tab DS.

Sheet SOURCE_OF_TRUTH
A1: Source of truth: mỗi loại thông tin có MỘT bản ghi gốc. Sổ tay mô tả cách làm; số liệu sống nằm ở đây.
A2: Thông tin | B2: Bản ghi gốc | C2: Ở đâu | D2: Ai cập nhật | E2: Ai được xem
A3: Trạng thái đơn, cờ SLA, ETA | B3: SOP Tracker · tab DON | C3: Tab DON | D3: Chủ trì từng giai đoạn (CX, SRC, LOG) | E3: Mọi vị trí (mã đơn, không dữ liệu cá nhân)
A4: Case khách và người duyệt | B4: SOP Tracker · tab CASE | C4: Tab CASE | D4: CX mở/đóng · người duyệt ghi tên · FIN ghi ngày hoàn | E4: CX, OPS, FIN, CEO
A5: Thông số, kích thước, màu, chất liệu | B5: Master SKU | C5: Tab MASTER_SKU | D5: SRC chốt thông số · MKT dùng để đăng | E5: Mọi vị trí (không có danh tính NCC)
A6: Bằng chứng NCC, PO, ảnh QC | B6: Thư mục NCC / PO / QC trên Drive | C6: Drive: thư mục NCC / PO / QC (hạn chế quyền) | D6: SRC | E6: SRC, OPS, CEO, FIN
A7: Chứng từ lô hàng | B7: Thư mục lô hàng theo container | C7: Drive: thư mục lô hàng theo container | D7: LOG | E7: LOG, OPS, CEO, FIN
A8: Landed cost thực, biên lãi | B8: File chi phí FIN · hạn chế quyền | C8: File chi phí FIN riêng · KHÔNG đặt trong sheet này | D8: FIN | E8: FIN, CEO (OPS xem phần cần)
A9: Lời hứa với khách | B9: Customer-facing Policy + email xác nhận đơn | C9: Sổ tay: Customer-facing Policy + mẫu email xác nhận | D9: CEO duyệt · OPS sửa | E9: Công khai
A10: Nội dung trang sản phẩm | B10: Listing đã duyệt từ Master SKU | C10: Shopify, đăng từ MASTER_SKU | D10: MKT | E10: Công khai sau khi duyệt

Sheet DASHBOARD
B2: Bảng điều khiển vận hành
B3: ="Hôm nay: "&TEXT(TODAY(),"dd/mm/yyyy")&" · từ tab DON và CASE"
B5: Đơn đang chạy | E5: Giao trong khung | H5: Đặt NCC ≤ 24h | K5: Cờ đỏ đơn đang mở | P5: Đơn theo trạng thái
B6: =COUNTA(DON!A3:A)-COUNTIF(DON!T3:T,"99*")-COUNTIF(DON!T3:T,"95*") | E6: =IFERROR(COUNTIF(DON!AB3:AB,"Có")/(COUNTIF(DON!AB3:AB,"Có")+COUNTIF(DON!AB3:AB,"Không")),"–") | H6: =IFERROR(COUNTIF(DON!AE3:AE,"<=1")/COUNT(DON!AE3:AE),"–") | K6: =COUNTIF(DON!W3:AA,"⚑") | P6: 10 Mới | Q6: =COUNTIF(DON!T3:T,"10 Mới")
E7: Mục tiêu ≥ 90% | H7: Mục tiêu ≥ 95% | K7: Mục tiêu 0 | P7: 20 Đã xác nhận | Q7: =COUNTIF(DON!T3:T,"20 Đã xác nhận")
P8: 30 Đã đặt NCC | Q8: =COUNTIF(DON!T3:T,"30 Đã đặt NCC")
B9: Case / đơn | E9: Phản hồi đầu (giờ, trung vị) | H9: Chargeback / đơn | K9: Chi phí case ròng (A$) | P9: 40 NCC đã gửi | Q9: =COUNTIF(DON!T3:T,"40 NCC đã gửi")
B10: =IFERROR(COUNTA(CASE!A3:A)/COUNTA(DON!A3:A),"–") | E10: =IFERROR(MEDIAN(CASE!T3:T),"–") | H10: =IFERROR(COUNTIF(CASE!C3:C,"C7*")/COUNTA(DON!A3:A),"–") | K10: =SUM(CASE!S3:S) | P10: 50 QC đạt | Q10: =COUNTIF(DON!T3:T,"50 QC đạt")
B11: Mục tiêu ≤ 3% | E11: Mục tiêu ≤ 4 | H11: Mục tiêu ≤ 0,5% | P11: 60 Đã xuất | Q11: =COUNTIF(DON!T3:T,"60 Đã xuất")
P12: 70 Thông quan | Q12: =COUNTIF(DON!T3:T,"70 Thông quan")
P13: 80 Đang giao | Q13: =COUNTIF(DON!T3:T,"80 Đang giao")
P14: 90 Đã giao | Q14: =COUNTIF(DON!T3:T,"90 Đã giao")
P15: 95 Hủy/hoàn | Q15: =COUNTIF(DON!T3:T,"95 Hủy/hoàn")
P16: 99 Đóng | Q16: =COUNTIF(DON!T3:T,"99 Đóng")
P18: Lead time TB (ngày)
P19: S1–S2 TT→Đặt NCC | Q19: =IFERROR(AVERAGE(DON!AE3:AE),0)
P20: S3 Đặt→NCC gửi | Q20: =IFERROR(AVERAGE(DON!AF3:AF),0)
P21: S4 Gửi→QC đạt | Q21: =IFERROR(AVERAGE(DON!AG3:AG),0)
P22: S5 QC→Xuất | Q22: =IFERROR(AVERAGE(DON!AH3:AH),0)
P23: S6–S7 Xuất→Giao | Q23: =IFERROR(AVERAGE(DON!AI3:AI),0)
P25: Cờ SLA đang bật
P26: Chưa đặt NCC >24h | Q26: =COUNTIF(DON!W3:W,"⚑")
P27: NCC quá hẹn >2d | Q27: =COUNTIF(DON!X3:X,"⚑")
P28: Sắp vượt ETA | Q28: =COUNTIF(DON!Y3:Y,"⚑")
P29: Vượt ETA | Q29: =COUNTIF(DON!Z3:Z,"⚑")
P30: >7d chưa cập nhật KH | Q30: =COUNTIF(DON!AA3:AA,"⚑")
P31: Case phản hồi >24h | Q31: =COUNTIF(CASE!V3:V,"⚑")
P32: Case mở >7 ngày | Q32: =COUNTIF(CASE!W3:W,"⚑")
P33: Case duyệt sai cấp | Q33: =COUNTIF(CASE!X3:X,"⚑")
P35: Case theo loại
P36: C1 Hủy đơn | Q36: =COUNTIF(CASE!C3:C,"C1 Hủy đơn")
P37: C2 Trễ hạn | Q37: =COUNTIF(CASE!C3:C,"C2 Trễ hạn")
P38: C3 Hư hỏng | Q38: =COUNTIF(CASE!C3:C,"C3 Hư hỏng")
P39: C4 Thiếu kiện/phụ kiện | Q39: =COUNTIF(CASE!C3:C,"C4 Thiếu kiện/phụ kiện")
P40: C5 Sai hàng/khác mô tả | Q40: =COUNTIF(CASE!C3:C,"C5 Sai hàng/khác mô tả")
P41: C6 Đổi ý | Q41: =COUNTIF(CASE!C3:C,"C6 Đổi ý")
P42: C7 Chargeback | Q42: =COUNTIF(CASE!C3:C,"C7 Chargeback")
P43: C8 Bảo hành | Q43: =COUNTIF(CASE!C3:C,"C8 Bảo hành")
P45: Case theo nguyên nhân gốc
P46: RC-NCC | Q46: =COUNTIF(CASE!P3:P,"RC-NCC")
...

Sheet DON
A1: SOP-A · Theo dõi đơn — nhập ngày khi có BẰNG CHỨNG · cột xám tự tính (không gõ đè) · màu tiêu đề = vị trí nhập
A2: Mã đơn | B2: Thị trường | C2: SKU | D2: Giá trị (A$) | E2: Ngày thanh toán | F2: ETA min | G2: ETA max (đã hứa) | H2: 20 Xác nhận | I2: 30 Đặt NCC | J2: Hẹn NCC gửi | K2: 40 NCC gửi | L2: 50 QC đạt | M2: 60 Xuất (quét thật) | N2: 70 Thông quan | O2: 80 Bàn giao giao cuối | P2: 90 Đã giao (POD) | Q2: 99 Đóng | R2: 95 Hủy/hoàn | S2: Cập nhật KH gần nhất | T2: Trạng thái | U2: Chủ trì hiện tại | V2: Ngày ở trạng thái | W2: ⚑ Chưa đặt NCC >24h | X2: ⚑ NCC quá hẹn >2d | Y2: ⚑ Sắp vượt ETA (≤14d) | Z2: ⚑ Vượt ETA | AA2: ⚑ >7d chưa cập nhật KH | AB2: Giao trong khung | AC2: Lead time tổng (ngày) | AD2: Số case | AE2: S1–S2 TT→Đặt NCC | AF2: S3 Đặt→NCC gửi | AG2: S4 Gửi→QC đạt | AH2: S5 QC→Xuất | AI2: S6–S7 Xuất→Giao
F3: =ARRAYFORMULA(IF(E3:E="","",E3:E+7*IFERROR(VLOOKUP(B3:B,DS!$K$2:$M$4,2,FALSE),12))) | G3: =ARRAYFORMULA(IF(E3:E="","",E3:E+7*IFERROR(VLOOKUP(B3:B,DS!$K$2:$M$4,3,FALSE),12))) | T3: =ARRAYFORMULA(IF(A3:A="","",IF(R3:R<>"","95 Hủy/hoàn",IF(Q3:Q<>"","99 Đóng",IF(P3:P<>"","90 Đã giao",IF(O3:O<>"","80 Đang giao",IF(N3:N<>"","70 Thông quan",IF(M3:M<>"","60 Đã xuất",IF(L3:L<>"","50 QC đạt",IF(K3:K<>"","40 NCC đã gửi",IF(I3:I<>"","30 Đã đặt NCC",IF(H3:H<>"","20 Đã xác nhận","10 Mới")))))))))))) | U3: =ARRAYFORMULA(IF(T3:T="","",IFERROR(VLOOKUP(T3:T,DS!$A$2:$B$12,2,FALSE),""))) | V3: =ARRAYFORMULA(IF((T3:T="")+(LEFT(T3:T,2)="99")+(LEFT(T3:T,2)="95"),"",TODAY()-IF(R3:R<>"",R3:R,IF(Q3:Q<>"",Q3:Q,IF(P3:P<>"",P3:P,IF(O3:O<>"",O3:O,IF(N3:N<>"",N3:N,IF(M3:M<>"",M3:M,IF(L3:L<>"",L3:L,IF(K3:K<>"",K3:K,IF(I3:I<>"",I3:I,IF(H3:H<>"",H3:H,E3:E)))))))))))) | W3: =ARRAYFORMULA(IF((E3:E<>"")*(I3:I="")*(R3:R=""),IF(TODAY()-E3:E>1,"⚑",""),"")) | X3: =ARRAYFORMULA(IF((J3:J<>"")*(K3:K="")*(R3:R=""),IF(TODAY()-J3:J>2,"⚑",""),"")) | Y3: =ARRAYFORMULA(IF((G3:G<>"")*(M3:M="")*(R3:R=""),IF((G3:G-TODAY()<=14)*(G3:G>=TODAY()),"⚑",""),"")) | Z3: =ARRAYFORMULA(IF((G3:G<>"")*(P3:P="")*(R3:R=""),IF(TODAY()>G3:G,"⚑",""),"")) | AA3: =ARRAYFORMULA(IF((E3:E<>"")*(P3:P="")*(R3:R=""),IF(TODAY()-BYROW({E3:E,H3:H,M3:M,S3:S},LAMBDA(r,MAX(r)))>7,"⚑",""),"")) | AB3: =ARRAYFORMULA(IF((P3:P="")+(G3:G=""),"",IF(P3:P<=G3:G,"Có","Không"))) | AC3: =ARRAYFORMULA(IF((P3:P="")+(E3:E=""),"",P3:P-E3:E)) | AD3: =ARRAYFORMULA(IF(A3:A="","",COUNTIF(CASE!B3:B,A3:A))) | AE3: =ARRAYFORMULA(IF((I3:I="")+(E3:E=""),"",I3:I-E3:E)) | AF3: =ARRAYFORMULA(IF((K3:K="")+(I3:I=""),"",K3:K-I3:I)) | AG3: =ARRAYFORMULA(IF((L3:L="")+(K3:K=""),"",L3:L-K3:K)) | AH3: =ARRAYFORMULA(IF((M3:M="")+(L3:L=""),"",M3:M-L3:L)) | AI3: =ARRAYFORMULA(IF((P3:P="")+(M3:M=""),"",P3:P-M3:M))

Sheet CASE
A1: SOP-B · Case hậu mãi — mỗi case một dòng · đóng case phải có nguyên nhân gốc
A2: Mã case | B2: Mã đơn | C2: Loại | D2: Kênh | E2: Mở lúc | F2: Phản hồi đầu lúc | G2: Đủ bằng chứng | H2: Giải pháp | I2: Đền bù / hoàn (A$) | J2: Cấp duyệt cần | K2: Người duyệt | L2: Đúng cấp? | M2: Thực thi xong | N2: Ngày hoàn tiền | O2: Đóng case | P2: Nguyên nhân gốc | Q2: Thu hồi từ | R2: Số thu hồi (A$) | S2: Chi phí ròng (A$) | T2: Giờ phản hồi | U2: Số ngày mở | V2: ⚑ Phản hồi >24h | W2: ⚑ Mở >7 ngày | X2: ⚑ Duyệt sai cấp | Y2: Ghi chú (không ghi dữ liệu cá nhân)
J3: =ARRAYFORMULA(IF(I3:I="","",IF((I3:I>150)+(H3:H="R4 Hoàn 100%"),"CEO",IF(I3:I>50,"OPS","CX")))) | L3: =ARRAYFORMULA(IF((J3:J="")+(K3:K=""),"",IF(IFERROR(MATCH(K3:K,DS!$H$2:$H$4,0),0)>=IFERROR(MATCH(J3:J,DS!$H$2:$H$4,0),9),"✓","✗"))) | S3: =ARRAYFORMULA(IF(A3:A="","",IFERROR(I3:I*1,0)-IFERROR(R3:R*1,0))) | T3: =ARRAYFORMULA(IF((E3:E="")+(F3:F=""),"",ROUND((F3:F-E3:E)*24,1))) | U3: =ARRAYFORMULA(IF(E3:E="","",INT(IF(O3:O="",NOW(),O3:O)-E3:E))) | V3: =ARRAYFORMULA(IF(E3:E="","",IF(F3:F="",IF((NOW()-E3:E)*24>24,"⚑",""),IF((F3:F-E3:E)*24>24,"⚑","")))) | W3: =ARRAYFORMULA(IF((E3:E="")+(O3:O<>""),"",IF(NOW()-E3:E>7,"⚑",""))) | X3: =ARRAYFORMULA(IF(L3:L="✗","⚑",""))

Sheet MASTER_SKU
A1: Master SKU: nguồn duy nhất cho thông số đăng web, nhãn, chứng từ. Chỉ ghi mã NCC nội bộ, không ghi tên/link NCC.
A2: Mã SP | B2: SKU biến thể | C2: Nhóm chính | D2: Nhóm con | E2: Tên tiếng Anh | F2: Màu chuẩn (mã) | G2: Chất liệu từng bộ phận | H2: Lớp phủ | I2: W (cm) | J2: D (cm) | K2: H (cm) | L2: Dung sai đăng web | M2: Số kiện | N2: KT + cân nặng từng kiện | O2: Lắp (phút) | P2: Cảnh báo đổ ngã (Y/N) | Q2: Gỗ / tre / mây (Y/N) | R2: Hướng dẫn lắp EN (link) | S2: Quyền dùng ảnh (bằng chứng) | T2: Hạng A/B/C | U2: Đạt 7 tiêu chí (Y/N) | V2: Mã NCC chính (nội bộ) | W2: Mã NCC dự phòng (nội bộ) | X2: Hàng mẫu đã kiểm (ngày) | Y2: Trạng thái listing | Z2: Người duyệt

Sheet LAUNCH_BLOCKERS
A1: Launch blockers: phải đóng trước khi đăng chính sách hoặc chạy quảng cáo.
A2: Mã | B2: Việc chưa xong | C2: Mô tả | D2: Chủ | E2: Trạng thái | F2: Ngày đóng · bằng chứng
A3: GST | B3: GST / thuế nhập khẩu | C3: Giá niêm yết đã gồm hay chưa gồm GST và thuế nhập khẩu: chờ chốt pháp nhân bán hàng và đăng ký GST. | D3: CEO | E3: Mở
A4: EMAIL | B4: Email hỗ trợ | C4: Chưa có email hỗ trợ chính thức cho chính sách và website. | D4: CEO | E4: Mở
A5: HOURS | B5: Giờ chăm sóc khách | C5: Chưa chốt giờ làm việc (AEST) công bố cho khách. | D5: CEO · OPS | E5: Mở
A6: LEGAL | B6: Luật sư Úc rà chính sách | C6: Chính sách giao hàng, đổi trả, hoàn tiền chưa được luật sư tại Úc (và Singapore) rà. | D6: CEO | E6: Mở
A7: BROKER | B7: Đại lý hải quan Úc | C7: Chưa có đại lý hải quan xác nhận mã HS và điều kiện nhập khẩu cho từng mã trước lô đầu tiên. | D7: CEO · LOG | E7: Mở

Sheet DS
A1: Trạng thái | B1: Chủ trì | E1: Loại case | G1: Giải pháp | H1: Cấp duyệt | I1: Nguyên nhân gốc | K1: Thị trường | L1: ETA min (tuần) | M1: ETA max (tuần) | O1: Kênh
A2: 10 Mới | B2: CX | E2: C1 Hủy đơn | G2: R1 Sửa | H2: CX | I2: RC-NCC | K2: AU | L2: 8 | M2: 12 | O2: Email
A3: 20 Đã xác nhận | B3: SRC | E3: C2 Trễ hạn | G3: R2 Gửi bù | H3: OPS | I3: RC-PACK | K3: SG | L3: 5 | M3: 8 | O3: Form web
A4: 30 Đã đặt NCC | B4: SRC | E4: C3 Hư hỏng | G4: R3 Đổi mới | H4: CEO | I4: RC-QC | K4: NZ | L4: 10 | M4: 14 | O4: Messenger
A5: 40 NCC đã gửi | B5: SRC | E5: C4 Thiếu kiện/phụ kiện | G5: R4 Hoàn một phần | I5: RC-FWD | O5: Instagram
A6: 50 QC đạt | B6: LOG | E6: C5 Sai hàng/khác mô tả | G6: R4 Hoàn 100% | I6: RC-LAST | K6: Khung ETA = chính sách đã công bố (sửa ở L2:M4). | O6: WhatsApp
A7: 60 Đã xuất | B7: LOG | E7: C6 Đổi ý | G7: R4 Tín dụng | I7: RC-LIST | O7: Điện thoại
A8: 70 Thông quan | B8: LOG | E8: C7 Chargeback | G8: R5 Thu hồi | I8: RC-CX | O8: Cổng thanh toán
A9: 80 Đang giao | B9: LOG | E9: C8 Bảo hành | G9: Không bồi thường | I9: RC-CUST
A10: 90 Đã giao | B10: CX
A11: 95 Hủy/hoàn | B11: –
A12: 99 Đóng | B12: –
